2025-06-01 16:27:37,669 | INFO | m00-backend | Iniciando m00-backend
2025-06-01 16:27:37,669 | INFO | m00-backend | === Teste de gravação em arquivo de log ===
2025-06-01 16:28:08,751 | INFO | m00-backend | Iniciando m00-backend
2025-06-01 16:28:08,752 | INFO | m00-backend | === Teste de gravação em arquivo de log ===
2025-06-01 16:31:24,219 | INFO | m00-backend | Iniciando m00-backend
2025-06-01 16:31:24,220 | INFO | m00-backend | === Teste de gravação em arquivo de log ===
2025-06-01 16:31:24,416 | INFO | m00-backend | Rota raiz acessada
2025-06-01 16:31:24,492 | ERROR | m00-backend | Erro inesperado em http://testserver/tasks/: (sqlite3.OperationalError) no such table: tasks
[SQL: SELECT tasks.id, tasks.title, tasks.description, tasks.completed 
FROM tasks]
(Background on this error at: https://sqlalche.me/e/20/e3q8)
Traceback (most recent call last):
  File "C:\Users\V\Documents\DEV-VINI\github\m00-projeto\venv\Lib\site-packages\sqlalchemy\engine\base.py", line 1963, in _exec_single_context
    self.dialect.do_execute(
    ~~~~~~~~~~~~~~~~~~~~~~~^
        cursor, str_statement, effective_parameters, context
        ^^^^^^^^^^^^^^^^^^^^^^^^^^^^^^^^^^^^^^^^^^^^^^^^^^^^
    )
    ^
  File "C:\Users\V\Documents\DEV-VINI\github\m00-projeto\venv\Lib\site-packages\sqlalchemy\engine\default.py", line 943, in do_execute
    cursor.execute(statement, parameters)
    ~~~~~~~~~~~~~~^^^^^^^^^^^^^^^^^^^^^^^
  File "C:\Users\V\Documents\DEV-VINI\github\m00-projeto\venv\Lib\site-packages\sqlalchemy\dialects\sqlite\aiosqlite.py", line 149, in execute
    self._adapt_connection._handle_exception(error)
    ~~~~~~~~~~~~~~~~~~~~~~~~~~~~~~~~~~~~~~~~^^^^^^^
  File "C:\Users\V\Documents\DEV-VINI\github\m00-projeto\venv\Lib\site-packages\sqlalchemy\dialects\sqlite\aiosqlite.py", line 300, in _handle_exception
    raise error
  File "C:\Users\V\Documents\DEV-VINI\github\m00-projeto\venv\Lib\site-packages\sqlalchemy\dialects\sqlite\aiosqlite.py", line 131, in execute
    self.await_(_cursor.execute(operation, parameters))
    ~~~~~~~~~~~^^^^^^^^^^^^^^^^^^^^^^^^^^^^^^^^^^^^^^^^
  File "C:\Users\V\Documents\DEV-VINI\github\m00-projeto\venv\Lib\site-packages\sqlalchemy\util\_concurrency_py3k.py", line 132, in await_only
    return current.parent.switch(awaitable)  # type: ignore[no-any-return,attr-defined] # noqa: E501
           ~~~~~~~~~~~~~~~~~~~~~^^^^^^^^^^^
  File "C:\Users\V\Documents\DEV-VINI\github\m00-projeto\venv\Lib\site-packages\sqlalchemy\util\_concurrency_py3k.py", line 196, in greenlet_spawn
    value = await result
            ^^^^^^^^^^^^
  File "C:\Users\V\Documents\DEV-VINI\github\m00-projeto\venv\Lib\site-packages\aiosqlite\cursor.py", line 40, in execute
    await self._execute(self._cursor.execute, sql, parameters)
  File "C:\Users\V\Documents\DEV-VINI\github\m00-projeto\venv\Lib\site-packages\aiosqlite\cursor.py", line 32, in _execute
    return await self._conn._execute(fn, *args, **kwargs)
           ^^^^^^^^^^^^^^^^^^^^^^^^^^^^^^^^^^^^^^^^^^^^^^
  File "C:\Users\V\Documents\DEV-VINI\github\m00-projeto\venv\Lib\site-packages\aiosqlite\core.py", line 122, in _execute
    return await future
           ^^^^^^^^^^^^
  File "C:\Users\V\Documents\DEV-VINI\github\m00-projeto\venv\Lib\site-packages\aiosqlite\core.py", line 105, in run
    result = function()
sqlite3.OperationalError: no such table: tasks

The above exception was the direct cause of the following exception:

Traceback (most recent call last):
  File "C:\Users\V\Documents\DEV-VINI\github\m00-projeto\venv\Lib\site-packages\starlette\middleware\errors.py", line 165, in __call__
    await self.app(scope, receive, _send)
  File "C:\Users\V\Documents\DEV-VINI\github\m00-projeto\venv\Lib\site-packages\starlette\middleware\exceptions.py", line 62, in __call__
    await wrap_app_handling_exceptions(self.app, conn)(scope, receive, send)
  File "C:\Users\V\Documents\DEV-VINI\github\m00-projeto\venv\Lib\site-packages\starlette\_exception_handler.py", line 53, in wrapped_app
    raise exc
  File "C:\Users\V\Documents\DEV-VINI\github\m00-projeto\venv\Lib\site-packages\starlette\_exception_handler.py", line 42, in wrapped_app
    await app(scope, receive, sender)
  File "C:\Users\V\Documents\DEV-VINI\github\m00-projeto\venv\Lib\site-packages\starlette\routing.py", line 714, in __call__
    await self.middleware_stack(scope, receive, send)
  File "C:\Users\V\Documents\DEV-VINI\github\m00-projeto\venv\Lib\site-packages\starlette\routing.py", line 734, in app
    await route.handle(scope, receive, send)
  File "C:\Users\V\Documents\DEV-VINI\github\m00-projeto\venv\Lib\site-packages\starlette\routing.py", line 288, in handle
    await self.app(scope, receive, send)
  File "C:\Users\V\Documents\DEV-VINI\github\m00-projeto\venv\Lib\site-packages\starlette\routing.py", line 76, in app
    await wrap_app_handling_exceptions(app, request)(scope, receive, send)
  File "C:\Users\V\Documents\DEV-VINI\github\m00-projeto\venv\Lib\site-packages\starlette\_exception_handler.py", line 53, in wrapped_app
    raise exc
  File "C:\Users\V\Documents\DEV-VINI\github\m00-projeto\venv\Lib\site-packages\starlette\_exception_handler.py", line 42, in wrapped_app
    await app(scope, receive, sender)
  File "C:\Users\V\Documents\DEV-VINI\github\m00-projeto\venv\Lib\site-packages\starlette\routing.py", line 73, in app
    response = await f(request)
               ^^^^^^^^^^^^^^^^
  File "C:\Users\V\Documents\DEV-VINI\github\m00-projeto\venv\Lib\site-packages\fastapi\routing.py", line 301, in app
    raw_response = await run_endpoint_function(
                   ^^^^^^^^^^^^^^^^^^^^^^^^^^^^
    ...<3 lines>...
    )
    ^
  File "C:\Users\V\Documents\DEV-VINI\github\m00-projeto\venv\Lib\site-packages\fastapi\routing.py", line 212, in run_endpoint_function
    return await dependant.call(**values)
           ^^^^^^^^^^^^^^^^^^^^^^^^^^^^^^
  File "C:\Users\V\Documents\DEV-VINI\github\m00-projeto\backend\app\api\tasks.py", line 38, in get_tasks
    result = await db.execute(select(TaskModel))
             ^^^^^^^^^^^^^^^^^^^^^^^^^^^^^^^^^^^
  File "C:\Users\V\Documents\DEV-VINI\github\m00-projeto\venv\Lib\site-packages\sqlalchemy\ext\asyncio\session.py", line 463, in execute
    result = await greenlet_spawn(
             ^^^^^^^^^^^^^^^^^^^^^
    ...<6 lines>...
    )
    ^
  File "C:\Users\V\Documents\DEV-VINI\github\m00-projeto\venv\Lib\site-packages\sqlalchemy\util\_concurrency_py3k.py", line 201, in greenlet_spawn
    result = context.throw(*sys.exc_info())
  File "C:\Users\V\Documents\DEV-VINI\github\m00-projeto\venv\Lib\site-packages\sqlalchemy\orm\session.py", line 2365, in execute
    return self._execute_internal(
           ~~~~~~~~~~~~~~~~~~~~~~^
        statement,
        ^^^^^^^^^^
    ...<4 lines>...
        _add_event=_add_event,
        ^^^^^^^^^^^^^^^^^^^^^^
    )
    ^
  File "C:\Users\V\Documents\DEV-VINI\github\m00-projeto\venv\Lib\site-packages\sqlalchemy\orm\session.py", line 2251, in _execute_internal
    result: Result[Any] = compile_state_cls.orm_execute_statement(
                          ~~~~~~~~~~~~~~~~~~~~~~~~~~~~~~~~~~~~~~~^
        self,
        ^^^^^
    ...<4 lines>...
        conn,
        ^^^^^
    )
    ^
  File "C:\Users\V\Documents\DEV-VINI\github\m00-projeto\venv\Lib\site-packages\sqlalchemy\orm\context.py", line 306, in orm_execute_statement
    result = conn.execute(
        statement, params or {}, execution_options=execution_options
    )
  File "C:\Users\V\Documents\DEV-VINI\github\m00-projeto\venv\Lib\site-packages\sqlalchemy\engine\base.py", line 1415, in execute
    return meth(
        self,
        distilled_parameters,
        execution_options or NO_OPTIONS,
    )
  File "C:\Users\V\Documents\DEV-VINI\github\m00-projeto\venv\Lib\site-packages\sqlalchemy\sql\elements.py", line 523, in _execute_on_connection
    return connection._execute_clauseelement(
           ~~~~~~~~~~~~~~~~~~~~~~~~~~~~~~~~~^
        self, distilled_params, execution_options
        ^^^^^^^^^^^^^^^^^^^^^^^^^^^^^^^^^^^^^^^^^
    )
    ^
  File "C:\Users\V\Documents\DEV-VINI\github\m00-projeto\venv\Lib\site-packages\sqlalchemy\engine\base.py", line 1637, in _execute_clauseelement
    ret = self._execute_context(
        dialect,
    ...<8 lines>...
        cache_hit=cache_hit,
    )
  File "C:\Users\V\Documents\DEV-VINI\github\m00-projeto\venv\Lib\site-packages\sqlalchemy\engine\base.py", line 1842, in _execute_context
    return self._exec_single_context(
           ~~~~~~~~~~~~~~~~~~~~~~~~~^
        dialect, context, statement, parameters
        ^^^^^^^^^^^^^^^^^^^^^^^^^^^^^^^^^^^^^^^
    )
    ^
  File "C:\Users\V\Documents\DEV-VINI\github\m00-projeto\venv\Lib\site-packages\sqlalchemy\engine\base.py", line 1982, in _exec_single_context
    self._handle_dbapi_exception(
    ~~~~~~~~~~~~~~~~~~~~~~~~~~~~^
        e, str_statement, effective_parameters, cursor, context
        ^^^^^^^^^^^^^^^^^^^^^^^^^^^^^^^^^^^^^^^^^^^^^^^^^^^^^^^
    )
    ^
  File "C:\Users\V\Documents\DEV-VINI\github\m00-projeto\venv\Lib\site-packages\sqlalchemy\engine\base.py", line 2351, in _handle_dbapi_exception
    raise sqlalchemy_exception.with_traceback(exc_info[2]) from e
  File "C:\Users\V\Documents\DEV-VINI\github\m00-projeto\venv\Lib\site-packages\sqlalchemy\engine\base.py", line 1963, in _exec_single_context
    self.dialect.do_execute(
    ~~~~~~~~~~~~~~~~~~~~~~~^
        cursor, str_statement, effective_parameters, context
        ^^^^^^^^^^^^^^^^^^^^^^^^^^^^^^^^^^^^^^^^^^^^^^^^^^^^
    )
    ^
  File "C:\Users\V\Documents\DEV-VINI\github\m00-projeto\venv\Lib\site-packages\sqlalchemy\engine\default.py", line 943, in do_execute
    cursor.execute(statement, parameters)
    ~~~~~~~~~~~~~~^^^^^^^^^^^^^^^^^^^^^^^
  File "C:\Users\V\Documents\DEV-VINI\github\m00-projeto\venv\Lib\site-packages\sqlalchemy\dialects\sqlite\aiosqlite.py", line 149, in execute
    self._adapt_connection._handle_exception(error)
    ~~~~~~~~~~~~~~~~~~~~~~~~~~~~~~~~~~~~~~~~^^^^^^^
  File "C:\Users\V\Documents\DEV-VINI\github\m00-projeto\venv\Lib\site-packages\sqlalchemy\dialects\sqlite\aiosqlite.py", line 300, in _handle_exception
    raise error
  File "C:\Users\V\Documents\DEV-VINI\github\m00-projeto\venv\Lib\site-packages\sqlalchemy\dialects\sqlite\aiosqlite.py", line 131, in execute
    self.await_(_cursor.execute(operation, parameters))
    ~~~~~~~~~~~^^^^^^^^^^^^^^^^^^^^^^^^^^^^^^^^^^^^^^^^
  File "C:\Users\V\Documents\DEV-VINI\github\m00-projeto\venv\Lib\site-packages\sqlalchemy\util\_concurrency_py3k.py", line 132, in await_only
    return current.parent.switch(awaitable)  # type: ignore[no-any-return,attr-defined] # noqa: E501
           ~~~~~~~~~~~~~~~~~~~~~^^^^^^^^^^^
  File "C:\Users\V\Documents\DEV-VINI\github\m00-projeto\venv\Lib\site-packages\sqlalchemy\util\_concurrency_py3k.py", line 196, in greenlet_spawn
    value = await result
            ^^^^^^^^^^^^
  File "C:\Users\V\Documents\DEV-VINI\github\m00-projeto\venv\Lib\site-packages\aiosqlite\cursor.py", line 40, in execute
    await self._execute(self._cursor.execute, sql, parameters)
  File "C:\Users\V\Documents\DEV-VINI\github\m00-projeto\venv\Lib\site-packages\aiosqlite\cursor.py", line 32, in _execute
    return await self._conn._execute(fn, *args, **kwargs)
           ^^^^^^^^^^^^^^^^^^^^^^^^^^^^^^^^^^^^^^^^^^^^^^
  File "C:\Users\V\Documents\DEV-VINI\github\m00-projeto\venv\Lib\site-packages\aiosqlite\core.py", line 122, in _execute
    return await future
           ^^^^^^^^^^^^
  File "C:\Users\V\Documents\DEV-VINI\github\m00-projeto\venv\Lib\site-packages\aiosqlite\core.py", line 105, in run
    result = function()
sqlalchemy.exc.OperationalError: (sqlite3.OperationalError) no such table: tasks
[SQL: SELECT tasks.id, tasks.title, tasks.description, tasks.completed 
FROM tasks]
(Background on this error at: https://sqlalche.me/e/20/e3q8)
2025-06-01 16:31:24,925 | ERROR | m00-backend | Erro inesperado em http://testserver/tasks/: (sqlite3.OperationalError) no such table: tasks
[SQL: INSERT INTO tasks (title, description, completed) VALUES (?, ?, ?)]
[parameters: ('Nova Tarefa', 'Descrição de teste', 0)]
(Background on this error at: https://sqlalche.me/e/20/e3q8)
Traceback (most recent call last):
  File "C:\Users\V\Documents\DEV-VINI\github\m00-projeto\venv\Lib\site-packages\sqlalchemy\engine\base.py", line 1963, in _exec_single_context
    self.dialect.do_execute(
    ~~~~~~~~~~~~~~~~~~~~~~~^
        cursor, str_statement, effective_parameters, context
        ^^^^^^^^^^^^^^^^^^^^^^^^^^^^^^^^^^^^^^^^^^^^^^^^^^^^
    )
    ^
  File "C:\Users\V\Documents\DEV-VINI\github\m00-projeto\venv\Lib\site-packages\sqlalchemy\engine\default.py", line 943, in do_execute
    cursor.execute(statement, parameters)
    ~~~~~~~~~~~~~~^^^^^^^^^^^^^^^^^^^^^^^
  File "C:\Users\V\Documents\DEV-VINI\github\m00-projeto\venv\Lib\site-packages\sqlalchemy\dialects\sqlite\aiosqlite.py", line 149, in execute
    self._adapt_connection._handle_exception(error)
    ~~~~~~~~~~~~~~~~~~~~~~~~~~~~~~~~~~~~~~~~^^^^^^^
  File "C:\Users\V\Documents\DEV-VINI\github\m00-projeto\venv\Lib\site-packages\sqlalchemy\dialects\sqlite\aiosqlite.py", line 300, in _handle_exception
    raise error
  File "C:\Users\V\Documents\DEV-VINI\github\m00-projeto\venv\Lib\site-packages\sqlalchemy\dialects\sqlite\aiosqlite.py", line 131, in execute
    self.await_(_cursor.execute(operation, parameters))
    ~~~~~~~~~~~^^^^^^^^^^^^^^^^^^^^^^^^^^^^^^^^^^^^^^^^
  File "C:\Users\V\Documents\DEV-VINI\github\m00-projeto\venv\Lib\site-packages\sqlalchemy\util\_concurrency_py3k.py", line 132, in await_only
    return current.parent.switch(awaitable)  # type: ignore[no-any-return,attr-defined] # noqa: E501
           ~~~~~~~~~~~~~~~~~~~~~^^^^^^^^^^^
  File "C:\Users\V\Documents\DEV-VINI\github\m00-projeto\venv\Lib\site-packages\sqlalchemy\util\_concurrency_py3k.py", line 196, in greenlet_spawn
    value = await result
            ^^^^^^^^^^^^
  File "C:\Users\V\Documents\DEV-VINI\github\m00-projeto\venv\Lib\site-packages\aiosqlite\cursor.py", line 40, in execute
    await self._execute(self._cursor.execute, sql, parameters)
  File "C:\Users\V\Documents\DEV-VINI\github\m00-projeto\venv\Lib\site-packages\aiosqlite\cursor.py", line 32, in _execute
    return await self._conn._execute(fn, *args, **kwargs)
           ^^^^^^^^^^^^^^^^^^^^^^^^^^^^^^^^^^^^^^^^^^^^^^
  File "C:\Users\V\Documents\DEV-VINI\github\m00-projeto\venv\Lib\site-packages\aiosqlite\core.py", line 122, in _execute
    return await future
           ^^^^^^^^^^^^
  File "C:\Users\V\Documents\DEV-VINI\github\m00-projeto\venv\Lib\site-packages\aiosqlite\core.py", line 105, in run
    result = function()
sqlite3.OperationalError: no such table: tasks

The above exception was the direct cause of the following exception:

Traceback (most recent call last):
  File "C:\Users\V\Documents\DEV-VINI\github\m00-projeto\venv\Lib\site-packages\starlette\middleware\errors.py", line 165, in __call__
    await self.app(scope, receive, _send)
  File "C:\Users\V\Documents\DEV-VINI\github\m00-projeto\venv\Lib\site-packages\starlette\middleware\exceptions.py", line 62, in __call__
    await wrap_app_handling_exceptions(self.app, conn)(scope, receive, send)
  File "C:\Users\V\Documents\DEV-VINI\github\m00-projeto\venv\Lib\site-packages\starlette\_exception_handler.py", line 53, in wrapped_app
    raise exc
  File "C:\Users\V\Documents\DEV-VINI\github\m00-projeto\venv\Lib\site-packages\starlette\_exception_handler.py", line 42, in wrapped_app
    await app(scope, receive, sender)
  File "C:\Users\V\Documents\DEV-VINI\github\m00-projeto\venv\Lib\site-packages\starlette\routing.py", line 714, in __call__
    await self.middleware_stack(scope, receive, send)
  File "C:\Users\V\Documents\DEV-VINI\github\m00-projeto\venv\Lib\site-packages\starlette\routing.py", line 734, in app
    await route.handle(scope, receive, send)
  File "C:\Users\V\Documents\DEV-VINI\github\m00-projeto\venv\Lib\site-packages\starlette\routing.py", line 288, in handle
    await self.app(scope, receive, send)
  File "C:\Users\V\Documents\DEV-VINI\github\m00-projeto\venv\Lib\site-packages\starlette\routing.py", line 76, in app
    await wrap_app_handling_exceptions(app, request)(scope, receive, send)
  File "C:\Users\V\Documents\DEV-VINI\github\m00-projeto\venv\Lib\site-packages\starlette\_exception_handler.py", line 53, in wrapped_app
    raise exc
  File "C:\Users\V\Documents\DEV-VINI\github\m00-projeto\venv\Lib\site-packages\starlette\_exception_handler.py", line 42, in wrapped_app
    await app(scope, receive, sender)
  File "C:\Users\V\Documents\DEV-VINI\github\m00-projeto\venv\Lib\site-packages\starlette\routing.py", line 73, in app
    response = await f(request)
               ^^^^^^^^^^^^^^^^
  File "C:\Users\V\Documents\DEV-VINI\github\m00-projeto\venv\Lib\site-packages\fastapi\routing.py", line 301, in app
    raw_response = await run_endpoint_function(
                   ^^^^^^^^^^^^^^^^^^^^^^^^^^^^
    ...<3 lines>...
    )
    ^
  File "C:\Users\V\Documents\DEV-VINI\github\m00-projeto\venv\Lib\site-packages\fastapi\routing.py", line 212, in run_endpoint_function
    return await dependant.call(**values)
           ^^^^^^^^^^^^^^^^^^^^^^^^^^^^^^
  File "C:\Users\V\Documents\DEV-VINI\github\m00-projeto\backend\app\api\tasks.py", line 29, in create_new_task
    task_created = await create_task(db, task)
                   ^^^^^^^^^^^^^^^^^^^^^^^^^^^
  File "C:\Users\V\Documents\DEV-VINI\github\m00-projeto\backend\app\services\task_service.py", line 23, in create_task
    await db.commit()
  File "C:\Users\V\Documents\DEV-VINI\github\m00-projeto\venv\Lib\site-packages\sqlalchemy\ext\asyncio\session.py", line 1014, in commit
    await greenlet_spawn(self.sync_session.commit)
  File "C:\Users\V\Documents\DEV-VINI\github\m00-projeto\venv\Lib\site-packages\sqlalchemy\util\_concurrency_py3k.py", line 203, in greenlet_spawn
    result = context.switch(value)
  File "C:\Users\V\Documents\DEV-VINI\github\m00-projeto\venv\Lib\site-packages\sqlalchemy\orm\session.py", line 2032, in commit
    trans.commit(_to_root=True)
    ~~~~~~~~~~~~^^^^^^^^^^^^^^^
  File "<string>", line 2, in commit
  File "C:\Users\V\Documents\DEV-VINI\github\m00-projeto\venv\Lib\site-packages\sqlalchemy\orm\state_changes.py", line 139, in _go
    ret_value = fn(self, *arg, **kw)
  File "C:\Users\V\Documents\DEV-VINI\github\m00-projeto\venv\Lib\site-packages\sqlalchemy\orm\session.py", line 1313, in commit
    self._prepare_impl()
    ~~~~~~~~~~~~~~~~~~^^
  File "<string>", line 2, in _prepare_impl
  File "C:\Users\V\Documents\DEV-VINI\github\m00-projeto\venv\Lib\site-packages\sqlalchemy\orm\state_changes.py", line 139, in _go
    ret_value = fn(self, *arg, **kw)
  File "C:\Users\V\Documents\DEV-VINI\github\m00-projeto\venv\Lib\site-packages\sqlalchemy\orm\session.py", line 1288, in _prepare_impl
    self.session.flush()
    ~~~~~~~~~~~~~~~~~~^^
  File "C:\Users\V\Documents\DEV-VINI\github\m00-projeto\venv\Lib\site-packages\sqlalchemy\orm\session.py", line 4345, in flush
    self._flush(objects)
    ~~~~~~~~~~~^^^^^^^^^
  File "C:\Users\V\Documents\DEV-VINI\github\m00-projeto\venv\Lib\site-packages\sqlalchemy\orm\session.py", line 4480, in _flush
    with util.safe_reraise():
         ~~~~~~~~~~~~~~~~~^^
  File "C:\Users\V\Documents\DEV-VINI\github\m00-projeto\venv\Lib\site-packages\sqlalchemy\util\langhelpers.py", line 224, in __exit__
    raise exc_value.with_traceback(exc_tb)
  File "C:\Users\V\Documents\DEV-VINI\github\m00-projeto\venv\Lib\site-packages\sqlalchemy\orm\session.py", line 4441, in _flush
    flush_context.execute()
    ~~~~~~~~~~~~~~~~~~~~~^^
  File "C:\Users\V\Documents\DEV-VINI\github\m00-projeto\venv\Lib\site-packages\sqlalchemy\orm\unitofwork.py", line 466, in execute
    rec.execute(self)
    ~~~~~~~~~~~^^^^^^
  File "C:\Users\V\Documents\DEV-VINI\github\m00-projeto\venv\Lib\site-packages\sqlalchemy\orm\unitofwork.py", line 642, in execute
    util.preloaded.orm_persistence.save_obj(
    ~~~~~~~~~~~~~~~~~~~~~~~~~~~~~~~~~~~~~~~^
        self.mapper,
        ^^^^^^^^^^^^
        uow.states_for_mapper_hierarchy(self.mapper, False, False),
        ^^^^^^^^^^^^^^^^^^^^^^^^^^^^^^^^^^^^^^^^^^^^^^^^^^^^^^^^^^^
        uow,
        ^^^^
    )
    ^
  File "C:\Users\V\Documents\DEV-VINI\github\m00-projeto\venv\Lib\site-packages\sqlalchemy\orm\persistence.py", line 93, in save_obj
    _emit_insert_statements(
    ~~~~~~~~~~~~~~~~~~~~~~~^
        base_mapper,
        ^^^^^^^^^^^^
    ...<3 lines>...
        insert,
        ^^^^^^^
    )
    ^
  File "C:\Users\V\Documents\DEV-VINI\github\m00-projeto\venv\Lib\site-packages\sqlalchemy\orm\persistence.py", line 1233, in _emit_insert_statements
    result = connection.execute(
        statement,
        params,
        execution_options=execution_options,
    )
  File "C:\Users\V\Documents\DEV-VINI\github\m00-projeto\venv\Lib\site-packages\sqlalchemy\engine\base.py", line 1415, in execute
    return meth(
        self,
        distilled_parameters,
        execution_options or NO_OPTIONS,
    )
  File "C:\Users\V\Documents\DEV-VINI\github\m00-projeto\venv\Lib\site-packages\sqlalchemy\sql\elements.py", line 523, in _execute_on_connection
    return connection._execute_clauseelement(
           ~~~~~~~~~~~~~~~~~~~~~~~~~~~~~~~~~^
        self, distilled_params, execution_options
        ^^^^^^^^^^^^^^^^^^^^^^^^^^^^^^^^^^^^^^^^^
    )
    ^
  File "C:\Users\V\Documents\DEV-VINI\github\m00-projeto\venv\Lib\site-packages\sqlalchemy\engine\base.py", line 1637, in _execute_clauseelement
    ret = self._execute_context(
        dialect,
    ...<8 lines>...
        cache_hit=cache_hit,
    )
  File "C:\Users\V\Documents\DEV-VINI\github\m00-projeto\venv\Lib\site-packages\sqlalchemy\engine\base.py", line 1842, in _execute_context
    return self._exec_single_context(
           ~~~~~~~~~~~~~~~~~~~~~~~~~^
        dialect, context, statement, parameters
        ^^^^^^^^^^^^^^^^^^^^^^^^^^^^^^^^^^^^^^^
    )
    ^
  File "C:\Users\V\Documents\DEV-VINI\github\m00-projeto\venv\Lib\site-packages\sqlalchemy\engine\base.py", line 1982, in _exec_single_context
    self._handle_dbapi_exception(
    ~~~~~~~~~~~~~~~~~~~~~~~~~~~~^
        e, str_statement, effective_parameters, cursor, context
        ^^^^^^^^^^^^^^^^^^^^^^^^^^^^^^^^^^^^^^^^^^^^^^^^^^^^^^^
    )
    ^
  File "C:\Users\V\Documents\DEV-VINI\github\m00-projeto\venv\Lib\site-packages\sqlalchemy\engine\base.py", line 2351, in _handle_dbapi_exception
    raise sqlalchemy_exception.with_traceback(exc_info[2]) from e
  File "C:\Users\V\Documents\DEV-VINI\github\m00-projeto\venv\Lib\site-packages\sqlalchemy\engine\base.py", line 1963, in _exec_single_context
    self.dialect.do_execute(
    ~~~~~~~~~~~~~~~~~~~~~~~^
        cursor, str_statement, effective_parameters, context
        ^^^^^^^^^^^^^^^^^^^^^^^^^^^^^^^^^^^^^^^^^^^^^^^^^^^^
    )
    ^
  File "C:\Users\V\Documents\DEV-VINI\github\m00-projeto\venv\Lib\site-packages\sqlalchemy\engine\default.py", line 943, in do_execute
    cursor.execute(statement, parameters)
    ~~~~~~~~~~~~~~^^^^^^^^^^^^^^^^^^^^^^^
  File "C:\Users\V\Documents\DEV-VINI\github\m00-projeto\venv\Lib\site-packages\sqlalchemy\dialects\sqlite\aiosqlite.py", line 149, in execute
    self._adapt_connection._handle_exception(error)
    ~~~~~~~~~~~~~~~~~~~~~~~~~~~~~~~~~~~~~~~~^^^^^^^
  File "C:\Users\V\Documents\DEV-VINI\github\m00-projeto\venv\Lib\site-packages\sqlalchemy\dialects\sqlite\aiosqlite.py", line 300, in _handle_exception
    raise error
  File "C:\Users\V\Documents\DEV-VINI\github\m00-projeto\venv\Lib\site-packages\sqlalchemy\dialects\sqlite\aiosqlite.py", line 131, in execute
    self.await_(_cursor.execute(operation, parameters))
    ~~~~~~~~~~~^^^^^^^^^^^^^^^^^^^^^^^^^^^^^^^^^^^^^^^^
  File "C:\Users\V\Documents\DEV-VINI\github\m00-projeto\venv\Lib\site-packages\sqlalchemy\util\_concurrency_py3k.py", line 132, in await_only
    return current.parent.switch(awaitable)  # type: ignore[no-any-return,attr-defined] # noqa: E501
           ~~~~~~~~~~~~~~~~~~~~~^^^^^^^^^^^
  File "C:\Users\V\Documents\DEV-VINI\github\m00-projeto\venv\Lib\site-packages\sqlalchemy\util\_concurrency_py3k.py", line 196, in greenlet_spawn
    value = await result
            ^^^^^^^^^^^^
  File "C:\Users\V\Documents\DEV-VINI\github\m00-projeto\venv\Lib\site-packages\aiosqlite\cursor.py", line 40, in execute
    await self._execute(self._cursor.execute, sql, parameters)
  File "C:\Users\V\Documents\DEV-VINI\github\m00-projeto\venv\Lib\site-packages\aiosqlite\cursor.py", line 32, in _execute
    return await self._conn._execute(fn, *args, **kwargs)
           ^^^^^^^^^^^^^^^^^^^^^^^^^^^^^^^^^^^^^^^^^^^^^^
  File "C:\Users\V\Documents\DEV-VINI\github\m00-projeto\venv\Lib\site-packages\aiosqlite\core.py", line 122, in _execute
    return await future
           ^^^^^^^^^^^^
  File "C:\Users\V\Documents\DEV-VINI\github\m00-projeto\venv\Lib\site-packages\aiosqlite\core.py", line 105, in run
    result = function()
sqlalchemy.exc.OperationalError: (sqlite3.OperationalError) no such table: tasks
[SQL: INSERT INTO tasks (title, description, completed) VALUES (?, ?, ?)]
[parameters: ('Nova Tarefa', 'Descrição de teste', 0)]
(Background on this error at: https://sqlalche.me/e/20/e3q8)
2025-06-01 16:31:25,432 | ERROR | m00-backend | Erro inesperado em http://testserver/tasks/: (sqlite3.OperationalError) no such table: tasks
[SQL: SELECT tasks.id, tasks.title, tasks.description, tasks.completed 
FROM tasks]
(Background on this error at: https://sqlalche.me/e/20/e3q8)
Traceback (most recent call last):
  File "C:\Users\V\Documents\DEV-VINI\github\m00-projeto\venv\Lib\site-packages\sqlalchemy\engine\base.py", line 1963, in _exec_single_context
    self.dialect.do_execute(
    ~~~~~~~~~~~~~~~~~~~~~~~^
        cursor, str_statement, effective_parameters, context
        ^^^^^^^^^^^^^^^^^^^^^^^^^^^^^^^^^^^^^^^^^^^^^^^^^^^^
    )
    ^
  File "C:\Users\V\Documents\DEV-VINI\github\m00-projeto\venv\Lib\site-packages\sqlalchemy\engine\default.py", line 943, in do_execute
    cursor.execute(statement, parameters)
    ~~~~~~~~~~~~~~^^^^^^^^^^^^^^^^^^^^^^^
  File "C:\Users\V\Documents\DEV-VINI\github\m00-projeto\venv\Lib\site-packages\sqlalchemy\dialects\sqlite\aiosqlite.py", line 149, in execute
    self._adapt_connection._handle_exception(error)
    ~~~~~~~~~~~~~~~~~~~~~~~~~~~~~~~~~~~~~~~~^^^^^^^
  File "C:\Users\V\Documents\DEV-VINI\github\m00-projeto\venv\Lib\site-packages\sqlalchemy\dialects\sqlite\aiosqlite.py", line 300, in _handle_exception
    raise error
  File "C:\Users\V\Documents\DEV-VINI\github\m00-projeto\venv\Lib\site-packages\sqlalchemy\dialects\sqlite\aiosqlite.py", line 131, in execute
    self.await_(_cursor.execute(operation, parameters))
    ~~~~~~~~~~~^^^^^^^^^^^^^^^^^^^^^^^^^^^^^^^^^^^^^^^^
  File "C:\Users\V\Documents\DEV-VINI\github\m00-projeto\venv\Lib\site-packages\sqlalchemy\util\_concurrency_py3k.py", line 132, in await_only
    return current.parent.switch(awaitable)  # type: ignore[no-any-return,attr-defined] # noqa: E501
           ~~~~~~~~~~~~~~~~~~~~~^^^^^^^^^^^
  File "C:\Users\V\Documents\DEV-VINI\github\m00-projeto\venv\Lib\site-packages\sqlalchemy\util\_concurrency_py3k.py", line 196, in greenlet_spawn
    value = await result
            ^^^^^^^^^^^^
  File "C:\Users\V\Documents\DEV-VINI\github\m00-projeto\venv\Lib\site-packages\aiosqlite\cursor.py", line 40, in execute
    await self._execute(self._cursor.execute, sql, parameters)
  File "C:\Users\V\Documents\DEV-VINI\github\m00-projeto\venv\Lib\site-packages\aiosqlite\cursor.py", line 32, in _execute
    return await self._conn._execute(fn, *args, **kwargs)
           ^^^^^^^^^^^^^^^^^^^^^^^^^^^^^^^^^^^^^^^^^^^^^^
  File "C:\Users\V\Documents\DEV-VINI\github\m00-projeto\venv\Lib\site-packages\aiosqlite\core.py", line 122, in _execute
    return await future
           ^^^^^^^^^^^^
  File "C:\Users\V\Documents\DEV-VINI\github\m00-projeto\venv\Lib\site-packages\aiosqlite\core.py", line 105, in run
    result = function()
sqlite3.OperationalError: no such table: tasks

The above exception was the direct cause of the following exception:

Traceback (most recent call last):
  File "C:\Users\V\Documents\DEV-VINI\github\m00-projeto\venv\Lib\site-packages\starlette\middleware\errors.py", line 165, in __call__
    await self.app(scope, receive, _send)
  File "C:\Users\V\Documents\DEV-VINI\github\m00-projeto\venv\Lib\site-packages\starlette\middleware\exceptions.py", line 62, in __call__
    await wrap_app_handling_exceptions(self.app, conn)(scope, receive, send)
  File "C:\Users\V\Documents\DEV-VINI\github\m00-projeto\venv\Lib\site-packages\starlette\_exception_handler.py", line 53, in wrapped_app
    raise exc
  File "C:\Users\V\Documents\DEV-VINI\github\m00-projeto\venv\Lib\site-packages\starlette\_exception_handler.py", line 42, in wrapped_app
    await app(scope, receive, sender)
  File "C:\Users\V\Documents\DEV-VINI\github\m00-projeto\venv\Lib\site-packages\starlette\routing.py", line 714, in __call__
    await self.middleware_stack(scope, receive, send)
  File "C:\Users\V\Documents\DEV-VINI\github\m00-projeto\venv\Lib\site-packages\starlette\routing.py", line 734, in app
    await route.handle(scope, receive, send)
  File "C:\Users\V\Documents\DEV-VINI\github\m00-projeto\venv\Lib\site-packages\starlette\routing.py", line 288, in handle
    await self.app(scope, receive, send)
  File "C:\Users\V\Documents\DEV-VINI\github\m00-projeto\venv\Lib\site-packages\starlette\routing.py", line 76, in app
    await wrap_app_handling_exceptions(app, request)(scope, receive, send)
  File "C:\Users\V\Documents\DEV-VINI\github\m00-projeto\venv\Lib\site-packages\starlette\_exception_handler.py", line 53, in wrapped_app
    raise exc
  File "C:\Users\V\Documents\DEV-VINI\github\m00-projeto\venv\Lib\site-packages\starlette\_exception_handler.py", line 42, in wrapped_app
    await app(scope, receive, sender)
  File "C:\Users\V\Documents\DEV-VINI\github\m00-projeto\venv\Lib\site-packages\starlette\routing.py", line 73, in app
    response = await f(request)
               ^^^^^^^^^^^^^^^^
  File "C:\Users\V\Documents\DEV-VINI\github\m00-projeto\venv\Lib\site-packages\fastapi\routing.py", line 301, in app
    raw_response = await run_endpoint_function(
                   ^^^^^^^^^^^^^^^^^^^^^^^^^^^^
    ...<3 lines>...
    )
    ^
  File "C:\Users\V\Documents\DEV-VINI\github\m00-projeto\venv\Lib\site-packages\fastapi\routing.py", line 212, in run_endpoint_function
    return await dependant.call(**values)
           ^^^^^^^^^^^^^^^^^^^^^^^^^^^^^^
  File "C:\Users\V\Documents\DEV-VINI\github\m00-projeto\backend\app\api\tasks.py", line 38, in get_tasks
    result = await db.execute(select(TaskModel))
             ^^^^^^^^^^^^^^^^^^^^^^^^^^^^^^^^^^^
  File "C:\Users\V\Documents\DEV-VINI\github\m00-projeto\venv\Lib\site-packages\sqlalchemy\ext\asyncio\session.py", line 463, in execute
    result = await greenlet_spawn(
             ^^^^^^^^^^^^^^^^^^^^^
    ...<6 lines>...
    )
    ^
  File "C:\Users\V\Documents\DEV-VINI\github\m00-projeto\venv\Lib\site-packages\sqlalchemy\util\_concurrency_py3k.py", line 201, in greenlet_spawn
    result = context.throw(*sys.exc_info())
  File "C:\Users\V\Documents\DEV-VINI\github\m00-projeto\venv\Lib\site-packages\sqlalchemy\orm\session.py", line 2365, in execute
    return self._execute_internal(
           ~~~~~~~~~~~~~~~~~~~~~~^
        statement,
        ^^^^^^^^^^
    ...<4 lines>...
        _add_event=_add_event,
        ^^^^^^^^^^^^^^^^^^^^^^
    )
    ^
  File "C:\Users\V\Documents\DEV-VINI\github\m00-projeto\venv\Lib\site-packages\sqlalchemy\orm\session.py", line 2251, in _execute_internal
    result: Result[Any] = compile_state_cls.orm_execute_statement(
                          ~~~~~~~~~~~~~~~~~~~~~~~~~~~~~~~~~~~~~~~^
        self,
        ^^^^^
    ...<4 lines>...
        conn,
        ^^^^^
    )
    ^
  File "C:\Users\V\Documents\DEV-VINI\github\m00-projeto\venv\Lib\site-packages\sqlalchemy\orm\context.py", line 306, in orm_execute_statement
    result = conn.execute(
        statement, params or {}, execution_options=execution_options
    )
  File "C:\Users\V\Documents\DEV-VINI\github\m00-projeto\venv\Lib\site-packages\sqlalchemy\engine\base.py", line 1415, in execute
    return meth(
        self,
        distilled_parameters,
        execution_options or NO_OPTIONS,
    )
  File "C:\Users\V\Documents\DEV-VINI\github\m00-projeto\venv\Lib\site-packages\sqlalchemy\sql\elements.py", line 523, in _execute_on_connection
    return connection._execute_clauseelement(
           ~~~~~~~~~~~~~~~~~~~~~~~~~~~~~~~~~^
        self, distilled_params, execution_options
        ^^^^^^^^^^^^^^^^^^^^^^^^^^^^^^^^^^^^^^^^^
    )
    ^
  File "C:\Users\V\Documents\DEV-VINI\github\m00-projeto\venv\Lib\site-packages\sqlalchemy\engine\base.py", line 1637, in _execute_clauseelement
    ret = self._execute_context(
        dialect,
    ...<8 lines>...
        cache_hit=cache_hit,
    )
  File "C:\Users\V\Documents\DEV-VINI\github\m00-projeto\venv\Lib\site-packages\sqlalchemy\engine\base.py", line 1842, in _execute_context
    return self._exec_single_context(
           ~~~~~~~~~~~~~~~~~~~~~~~~~^
        dialect, context, statement, parameters
        ^^^^^^^^^^^^^^^^^^^^^^^^^^^^^^^^^^^^^^^
    )
    ^
  File "C:\Users\V\Documents\DEV-VINI\github\m00-projeto\venv\Lib\site-packages\sqlalchemy\engine\base.py", line 1982, in _exec_single_context
    self._handle_dbapi_exception(
    ~~~~~~~~~~~~~~~~~~~~~~~~~~~~^
        e, str_statement, effective_parameters, cursor, context
        ^^^^^^^^^^^^^^^^^^^^^^^^^^^^^^^^^^^^^^^^^^^^^^^^^^^^^^^
    )
    ^
  File "C:\Users\V\Documents\DEV-VINI\github\m00-projeto\venv\Lib\site-packages\sqlalchemy\engine\base.py", line 2351, in _handle_dbapi_exception
    raise sqlalchemy_exception.with_traceback(exc_info[2]) from e
  File "C:\Users\V\Documents\DEV-VINI\github\m00-projeto\venv\Lib\site-packages\sqlalchemy\engine\base.py", line 1963, in _exec_single_context
    self.dialect.do_execute(
    ~~~~~~~~~~~~~~~~~~~~~~~^
        cursor, str_statement, effective_parameters, context
        ^^^^^^^^^^^^^^^^^^^^^^^^^^^^^^^^^^^^^^^^^^^^^^^^^^^^
    )
    ^
  File "C:\Users\V\Documents\DEV-VINI\github\m00-projeto\venv\Lib\site-packages\sqlalchemy\engine\default.py", line 943, in do_execute
    cursor.execute(statement, parameters)
    ~~~~~~~~~~~~~~^^^^^^^^^^^^^^^^^^^^^^^
  File "C:\Users\V\Documents\DEV-VINI\github\m00-projeto\venv\Lib\site-packages\sqlalchemy\dialects\sqlite\aiosqlite.py", line 149, in execute
    self._adapt_connection._handle_exception(error)
    ~~~~~~~~~~~~~~~~~~~~~~~~~~~~~~~~~~~~~~~~^^^^^^^
  File "C:\Users\V\Documents\DEV-VINI\github\m00-projeto\venv\Lib\site-packages\sqlalchemy\dialects\sqlite\aiosqlite.py", line 300, in _handle_exception
    raise error
  File "C:\Users\V\Documents\DEV-VINI\github\m00-projeto\venv\Lib\site-packages\sqlalchemy\dialects\sqlite\aiosqlite.py", line 131, in execute
    self.await_(_cursor.execute(operation, parameters))
    ~~~~~~~~~~~^^^^^^^^^^^^^^^^^^^^^^^^^^^^^^^^^^^^^^^^
  File "C:\Users\V\Documents\DEV-VINI\github\m00-projeto\venv\Lib\site-packages\sqlalchemy\util\_concurrency_py3k.py", line 132, in await_only
    return current.parent.switch(awaitable)  # type: ignore[no-any-return,attr-defined] # noqa: E501
           ~~~~~~~~~~~~~~~~~~~~~^^^^^^^^^^^
  File "C:\Users\V\Documents\DEV-VINI\github\m00-projeto\venv\Lib\site-packages\sqlalchemy\util\_concurrency_py3k.py", line 196, in greenlet_spawn
    value = await result
            ^^^^^^^^^^^^
  File "C:\Users\V\Documents\DEV-VINI\github\m00-projeto\venv\Lib\site-packages\aiosqlite\cursor.py", line 40, in execute
    await self._execute(self._cursor.execute, sql, parameters)
  File "C:\Users\V\Documents\DEV-VINI\github\m00-projeto\venv\Lib\site-packages\aiosqlite\cursor.py", line 32, in _execute
    return await self._conn._execute(fn, *args, **kwargs)
           ^^^^^^^^^^^^^^^^^^^^^^^^^^^^^^^^^^^^^^^^^^^^^^
  File "C:\Users\V\Documents\DEV-VINI\github\m00-projeto\venv\Lib\site-packages\aiosqlite\core.py", line 122, in _execute
    return await future
           ^^^^^^^^^^^^
  File "C:\Users\V\Documents\DEV-VINI\github\m00-projeto\venv\Lib\site-packages\aiosqlite\core.py", line 105, in run
    result = function()
sqlalchemy.exc.OperationalError: (sqlite3.OperationalError) no such table: tasks
[SQL: SELECT tasks.id, tasks.title, tasks.description, tasks.completed 
FROM tasks]
(Background on this error at: https://sqlalche.me/e/20/e3q8)
2025-06-01 16:31:25,843 | ERROR | m00-backend | Erro inesperado em http://testserver/tasks/: (sqlite3.OperationalError) no such table: tasks
[SQL: INSERT INTO tasks (title, description, completed) VALUES (?, ?, ?)]
[parameters: ('Tarefa para GET', 'Desc GET', 0)]
(Background on this error at: https://sqlalche.me/e/20/e3q8)
Traceback (most recent call last):
  File "C:\Users\V\Documents\DEV-VINI\github\m00-projeto\venv\Lib\site-packages\sqlalchemy\engine\base.py", line 1963, in _exec_single_context
    self.dialect.do_execute(
    ~~~~~~~~~~~~~~~~~~~~~~~^
        cursor, str_statement, effective_parameters, context
        ^^^^^^^^^^^^^^^^^^^^^^^^^^^^^^^^^^^^^^^^^^^^^^^^^^^^
    )
    ^
  File "C:\Users\V\Documents\DEV-VINI\github\m00-projeto\venv\Lib\site-packages\sqlalchemy\engine\default.py", line 943, in do_execute
    cursor.execute(statement, parameters)
    ~~~~~~~~~~~~~~^^^^^^^^^^^^^^^^^^^^^^^
  File "C:\Users\V\Documents\DEV-VINI\github\m00-projeto\venv\Lib\site-packages\sqlalchemy\dialects\sqlite\aiosqlite.py", line 149, in execute
    self._adapt_connection._handle_exception(error)
    ~~~~~~~~~~~~~~~~~~~~~~~~~~~~~~~~~~~~~~~~^^^^^^^
  File "C:\Users\V\Documents\DEV-VINI\github\m00-projeto\venv\Lib\site-packages\sqlalchemy\dialects\sqlite\aiosqlite.py", line 300, in _handle_exception
    raise error
  File "C:\Users\V\Documents\DEV-VINI\github\m00-projeto\venv\Lib\site-packages\sqlalchemy\dialects\sqlite\aiosqlite.py", line 131, in execute
    self.await_(_cursor.execute(operation, parameters))
    ~~~~~~~~~~~^^^^^^^^^^^^^^^^^^^^^^^^^^^^^^^^^^^^^^^^
  File "C:\Users\V\Documents\DEV-VINI\github\m00-projeto\venv\Lib\site-packages\sqlalchemy\util\_concurrency_py3k.py", line 132, in await_only
    return current.parent.switch(awaitable)  # type: ignore[no-any-return,attr-defined] # noqa: E501
           ~~~~~~~~~~~~~~~~~~~~~^^^^^^^^^^^
  File "C:\Users\V\Documents\DEV-VINI\github\m00-projeto\venv\Lib\site-packages\sqlalchemy\util\_concurrency_py3k.py", line 196, in greenlet_spawn
    value = await result
            ^^^^^^^^^^^^
  File "C:\Users\V\Documents\DEV-VINI\github\m00-projeto\venv\Lib\site-packages\aiosqlite\cursor.py", line 40, in execute
    await self._execute(self._cursor.execute, sql, parameters)
  File "C:\Users\V\Documents\DEV-VINI\github\m00-projeto\venv\Lib\site-packages\aiosqlite\cursor.py", line 32, in _execute
    return await self._conn._execute(fn, *args, **kwargs)
           ^^^^^^^^^^^^^^^^^^^^^^^^^^^^^^^^^^^^^^^^^^^^^^
  File "C:\Users\V\Documents\DEV-VINI\github\m00-projeto\venv\Lib\site-packages\aiosqlite\core.py", line 122, in _execute
    return await future
           ^^^^^^^^^^^^
  File "C:\Users\V\Documents\DEV-VINI\github\m00-projeto\venv\Lib\site-packages\aiosqlite\core.py", line 105, in run
    result = function()
sqlite3.OperationalError: no such table: tasks

The above exception was the direct cause of the following exception:

Traceback (most recent call last):
  File "C:\Users\V\Documents\DEV-VINI\github\m00-projeto\venv\Lib\site-packages\starlette\middleware\errors.py", line 165, in __call__
    await self.app(scope, receive, _send)
  File "C:\Users\V\Documents\DEV-VINI\github\m00-projeto\venv\Lib\site-packages\starlette\middleware\exceptions.py", line 62, in __call__
    await wrap_app_handling_exceptions(self.app, conn)(scope, receive, send)
  File "C:\Users\V\Documents\DEV-VINI\github\m00-projeto\venv\Lib\site-packages\starlette\_exception_handler.py", line 53, in wrapped_app
    raise exc
  File "C:\Users\V\Documents\DEV-VINI\github\m00-projeto\venv\Lib\site-packages\starlette\_exception_handler.py", line 42, in wrapped_app
    await app(scope, receive, sender)
  File "C:\Users\V\Documents\DEV-VINI\github\m00-projeto\venv\Lib\site-packages\starlette\routing.py", line 714, in __call__
    await self.middleware_stack(scope, receive, send)
  File "C:\Users\V\Documents\DEV-VINI\github\m00-projeto\venv\Lib\site-packages\starlette\routing.py", line 734, in app
    await route.handle(scope, receive, send)
  File "C:\Users\V\Documents\DEV-VINI\github\m00-projeto\venv\Lib\site-packages\starlette\routing.py", line 288, in handle
    await self.app(scope, receive, send)
  File "C:\Users\V\Documents\DEV-VINI\github\m00-projeto\venv\Lib\site-packages\starlette\routing.py", line 76, in app
    await wrap_app_handling_exceptions(app, request)(scope, receive, send)
  File "C:\Users\V\Documents\DEV-VINI\github\m00-projeto\venv\Lib\site-packages\starlette\_exception_handler.py", line 53, in wrapped_app
    raise exc
  File "C:\Users\V\Documents\DEV-VINI\github\m00-projeto\venv\Lib\site-packages\starlette\_exception_handler.py", line 42, in wrapped_app
    await app(scope, receive, sender)
  File "C:\Users\V\Documents\DEV-VINI\github\m00-projeto\venv\Lib\site-packages\starlette\routing.py", line 73, in app
    response = await f(request)
               ^^^^^^^^^^^^^^^^
  File "C:\Users\V\Documents\DEV-VINI\github\m00-projeto\venv\Lib\site-packages\fastapi\routing.py", line 301, in app
    raw_response = await run_endpoint_function(
                   ^^^^^^^^^^^^^^^^^^^^^^^^^^^^
    ...<3 lines>...
    )
    ^
  File "C:\Users\V\Documents\DEV-VINI\github\m00-projeto\venv\Lib\site-packages\fastapi\routing.py", line 212, in run_endpoint_function
    return await dependant.call(**values)
           ^^^^^^^^^^^^^^^^^^^^^^^^^^^^^^
  File "C:\Users\V\Documents\DEV-VINI\github\m00-projeto\backend\app\api\tasks.py", line 29, in create_new_task
    task_created = await create_task(db, task)
                   ^^^^^^^^^^^^^^^^^^^^^^^^^^^
  File "C:\Users\V\Documents\DEV-VINI\github\m00-projeto\backend\app\services\task_service.py", line 23, in create_task
    await db.commit()
  File "C:\Users\V\Documents\DEV-VINI\github\m00-projeto\venv\Lib\site-packages\sqlalchemy\ext\asyncio\session.py", line 1014, in commit
    await greenlet_spawn(self.sync_session.commit)
  File "C:\Users\V\Documents\DEV-VINI\github\m00-projeto\venv\Lib\site-packages\sqlalchemy\util\_concurrency_py3k.py", line 203, in greenlet_spawn
    result = context.switch(value)
  File "C:\Users\V\Documents\DEV-VINI\github\m00-projeto\venv\Lib\site-packages\sqlalchemy\orm\session.py", line 2032, in commit
    trans.commit(_to_root=True)
    ~~~~~~~~~~~~^^^^^^^^^^^^^^^
  File "<string>", line 2, in commit
  File "C:\Users\V\Documents\DEV-VINI\github\m00-projeto\venv\Lib\site-packages\sqlalchemy\orm\state_changes.py", line 139, in _go
    ret_value = fn(self, *arg, **kw)
  File "C:\Users\V\Documents\DEV-VINI\github\m00-projeto\venv\Lib\site-packages\sqlalchemy\orm\session.py", line 1313, in commit
    self._prepare_impl()
    ~~~~~~~~~~~~~~~~~~^^
  File "<string>", line 2, in _prepare_impl
  File "C:\Users\V\Documents\DEV-VINI\github\m00-projeto\venv\Lib\site-packages\sqlalchemy\orm\state_changes.py", line 139, in _go
    ret_value = fn(self, *arg, **kw)
  File "C:\Users\V\Documents\DEV-VINI\github\m00-projeto\venv\Lib\site-packages\sqlalchemy\orm\session.py", line 1288, in _prepare_impl
    self.session.flush()
    ~~~~~~~~~~~~~~~~~~^^
  File "C:\Users\V\Documents\DEV-VINI\github\m00-projeto\venv\Lib\site-packages\sqlalchemy\orm\session.py", line 4345, in flush
    self._flush(objects)
    ~~~~~~~~~~~^^^^^^^^^
  File "C:\Users\V\Documents\DEV-VINI\github\m00-projeto\venv\Lib\site-packages\sqlalchemy\orm\session.py", line 4480, in _flush
    with util.safe_reraise():
         ~~~~~~~~~~~~~~~~~^^
  File "C:\Users\V\Documents\DEV-VINI\github\m00-projeto\venv\Lib\site-packages\sqlalchemy\util\langhelpers.py", line 224, in __exit__
    raise exc_value.with_traceback(exc_tb)
  File "C:\Users\V\Documents\DEV-VINI\github\m00-projeto\venv\Lib\site-packages\sqlalchemy\orm\session.py", line 4441, in _flush
    flush_context.execute()
    ~~~~~~~~~~~~~~~~~~~~~^^
  File "C:\Users\V\Documents\DEV-VINI\github\m00-projeto\venv\Lib\site-packages\sqlalchemy\orm\unitofwork.py", line 466, in execute
    rec.execute(self)
    ~~~~~~~~~~~^^^^^^
  File "C:\Users\V\Documents\DEV-VINI\github\m00-projeto\venv\Lib\site-packages\sqlalchemy\orm\unitofwork.py", line 642, in execute
    util.preloaded.orm_persistence.save_obj(
    ~~~~~~~~~~~~~~~~~~~~~~~~~~~~~~~~~~~~~~~^
        self.mapper,
        ^^^^^^^^^^^^
        uow.states_for_mapper_hierarchy(self.mapper, False, False),
        ^^^^^^^^^^^^^^^^^^^^^^^^^^^^^^^^^^^^^^^^^^^^^^^^^^^^^^^^^^^
        uow,
        ^^^^
    )
    ^
  File "C:\Users\V\Documents\DEV-VINI\github\m00-projeto\venv\Lib\site-packages\sqlalchemy\orm\persistence.py", line 93, in save_obj
    _emit_insert_statements(
    ~~~~~~~~~~~~~~~~~~~~~~~^
        base_mapper,
        ^^^^^^^^^^^^
    ...<3 lines>...
        insert,
        ^^^^^^^
    )
    ^
  File "C:\Users\V\Documents\DEV-VINI\github\m00-projeto\venv\Lib\site-packages\sqlalchemy\orm\persistence.py", line 1233, in _emit_insert_statements
    result = connection.execute(
        statement,
        params,
        execution_options=execution_options,
    )
  File "C:\Users\V\Documents\DEV-VINI\github\m00-projeto\venv\Lib\site-packages\sqlalchemy\engine\base.py", line 1415, in execute
    return meth(
        self,
        distilled_parameters,
        execution_options or NO_OPTIONS,
    )
  File "C:\Users\V\Documents\DEV-VINI\github\m00-projeto\venv\Lib\site-packages\sqlalchemy\sql\elements.py", line 523, in _execute_on_connection
    return connection._execute_clauseelement(
           ~~~~~~~~~~~~~~~~~~~~~~~~~~~~~~~~~^
        self, distilled_params, execution_options
        ^^^^^^^^^^^^^^^^^^^^^^^^^^^^^^^^^^^^^^^^^
    )
    ^
  File "C:\Users\V\Documents\DEV-VINI\github\m00-projeto\venv\Lib\site-packages\sqlalchemy\engine\base.py", line 1637, in _execute_clauseelement
    ret = self._execute_context(
        dialect,
    ...<8 lines>...
        cache_hit=cache_hit,
    )
  File "C:\Users\V\Documents\DEV-VINI\github\m00-projeto\venv\Lib\site-packages\sqlalchemy\engine\base.py", line 1842, in _execute_context
    return self._exec_single_context(
           ~~~~~~~~~~~~~~~~~~~~~~~~~^
        dialect, context, statement, parameters
        ^^^^^^^^^^^^^^^^^^^^^^^^^^^^^^^^^^^^^^^
    )
    ^
  File "C:\Users\V\Documents\DEV-VINI\github\m00-projeto\venv\Lib\site-packages\sqlalchemy\engine\base.py", line 1982, in _exec_single_context
    self._handle_dbapi_exception(
    ~~~~~~~~~~~~~~~~~~~~~~~~~~~~^
        e, str_statement, effective_parameters, cursor, context
        ^^^^^^^^^^^^^^^^^^^^^^^^^^^^^^^^^^^^^^^^^^^^^^^^^^^^^^^
    )
    ^
  File "C:\Users\V\Documents\DEV-VINI\github\m00-projeto\venv\Lib\site-packages\sqlalchemy\engine\base.py", line 2351, in _handle_dbapi_exception
    raise sqlalchemy_exception.with_traceback(exc_info[2]) from e
  File "C:\Users\V\Documents\DEV-VINI\github\m00-projeto\venv\Lib\site-packages\sqlalchemy\engine\base.py", line 1963, in _exec_single_context
    self.dialect.do_execute(
    ~~~~~~~~~~~~~~~~~~~~~~~^
        cursor, str_statement, effective_parameters, context
        ^^^^^^^^^^^^^^^^^^^^^^^^^^^^^^^^^^^^^^^^^^^^^^^^^^^^
    )
    ^
  File "C:\Users\V\Documents\DEV-VINI\github\m00-projeto\venv\Lib\site-packages\sqlalchemy\engine\default.py", line 943, in do_execute
    cursor.execute(statement, parameters)
    ~~~~~~~~~~~~~~^^^^^^^^^^^^^^^^^^^^^^^
  File "C:\Users\V\Documents\DEV-VINI\github\m00-projeto\venv\Lib\site-packages\sqlalchemy\dialects\sqlite\aiosqlite.py", line 149, in execute
    self._adapt_connection._handle_exception(error)
    ~~~~~~~~~~~~~~~~~~~~~~~~~~~~~~~~~~~~~~~~^^^^^^^
  File "C:\Users\V\Documents\DEV-VINI\github\m00-projeto\venv\Lib\site-packages\sqlalchemy\dialects\sqlite\aiosqlite.py", line 300, in _handle_exception
    raise error
  File "C:\Users\V\Documents\DEV-VINI\github\m00-projeto\venv\Lib\site-packages\sqlalchemy\dialects\sqlite\aiosqlite.py", line 131, in execute
    self.await_(_cursor.execute(operation, parameters))
    ~~~~~~~~~~~^^^^^^^^^^^^^^^^^^^^^^^^^^^^^^^^^^^^^^^^
  File "C:\Users\V\Documents\DEV-VINI\github\m00-projeto\venv\Lib\site-packages\sqlalchemy\util\_concurrency_py3k.py", line 132, in await_only
    return current.parent.switch(awaitable)  # type: ignore[no-any-return,attr-defined] # noqa: E501
           ~~~~~~~~~~~~~~~~~~~~~^^^^^^^^^^^
  File "C:\Users\V\Documents\DEV-VINI\github\m00-projeto\venv\Lib\site-packages\sqlalchemy\util\_concurrency_py3k.py", line 196, in greenlet_spawn
    value = await result
            ^^^^^^^^^^^^
  File "C:\Users\V\Documents\DEV-VINI\github\m00-projeto\venv\Lib\site-packages\aiosqlite\cursor.py", line 40, in execute
    await self._execute(self._cursor.execute, sql, parameters)
  File "C:\Users\V\Documents\DEV-VINI\github\m00-projeto\venv\Lib\site-packages\aiosqlite\cursor.py", line 32, in _execute
    return await self._conn._execute(fn, *args, **kwargs)
           ^^^^^^^^^^^^^^^^^^^^^^^^^^^^^^^^^^^^^^^^^^^^^^
  File "C:\Users\V\Documents\DEV-VINI\github\m00-projeto\venv\Lib\site-packages\aiosqlite\core.py", line 122, in _execute
    return await future
           ^^^^^^^^^^^^
  File "C:\Users\V\Documents\DEV-VINI\github\m00-projeto\venv\Lib\site-packages\aiosqlite\core.py", line 105, in run
    result = function()
sqlalchemy.exc.OperationalError: (sqlite3.OperationalError) no such table: tasks
[SQL: INSERT INTO tasks (title, description, completed) VALUES (?, ?, ?)]
[parameters: ('Tarefa para GET', 'Desc GET', 0)]
(Background on this error at: https://sqlalche.me/e/20/e3q8)
2025-06-01 16:31:26,383 | ERROR | m00-backend | Erro inesperado em http://testserver/tasks/: (sqlite3.OperationalError) no such table: tasks
[SQL: INSERT INTO tasks (title, description, completed) VALUES (?, ?, ?)]
[parameters: ('Tarefa PUT', 'Desc PUT', 0)]
(Background on this error at: https://sqlalche.me/e/20/e3q8)
Traceback (most recent call last):
  File "C:\Users\V\Documents\DEV-VINI\github\m00-projeto\venv\Lib\site-packages\sqlalchemy\engine\base.py", line 1963, in _exec_single_context
    self.dialect.do_execute(
    ~~~~~~~~~~~~~~~~~~~~~~~^
        cursor, str_statement, effective_parameters, context
        ^^^^^^^^^^^^^^^^^^^^^^^^^^^^^^^^^^^^^^^^^^^^^^^^^^^^
    )
    ^
  File "C:\Users\V\Documents\DEV-VINI\github\m00-projeto\venv\Lib\site-packages\sqlalchemy\engine\default.py", line 943, in do_execute
    cursor.execute(statement, parameters)
    ~~~~~~~~~~~~~~^^^^^^^^^^^^^^^^^^^^^^^
  File "C:\Users\V\Documents\DEV-VINI\github\m00-projeto\venv\Lib\site-packages\sqlalchemy\dialects\sqlite\aiosqlite.py", line 149, in execute
    self._adapt_connection._handle_exception(error)
    ~~~~~~~~~~~~~~~~~~~~~~~~~~~~~~~~~~~~~~~~^^^^^^^
  File "C:\Users\V\Documents\DEV-VINI\github\m00-projeto\venv\Lib\site-packages\sqlalchemy\dialects\sqlite\aiosqlite.py", line 300, in _handle_exception
    raise error
  File "C:\Users\V\Documents\DEV-VINI\github\m00-projeto\venv\Lib\site-packages\sqlalchemy\dialects\sqlite\aiosqlite.py", line 131, in execute
    self.await_(_cursor.execute(operation, parameters))
    ~~~~~~~~~~~^^^^^^^^^^^^^^^^^^^^^^^^^^^^^^^^^^^^^^^^
  File "C:\Users\V\Documents\DEV-VINI\github\m00-projeto\venv\Lib\site-packages\sqlalchemy\util\_concurrency_py3k.py", line 132, in await_only
    return current.parent.switch(awaitable)  # type: ignore[no-any-return,attr-defined] # noqa: E501
           ~~~~~~~~~~~~~~~~~~~~~^^^^^^^^^^^
  File "C:\Users\V\Documents\DEV-VINI\github\m00-projeto\venv\Lib\site-packages\sqlalchemy\util\_concurrency_py3k.py", line 196, in greenlet_spawn
    value = await result
            ^^^^^^^^^^^^
  File "C:\Users\V\Documents\DEV-VINI\github\m00-projeto\venv\Lib\site-packages\aiosqlite\cursor.py", line 40, in execute
    await self._execute(self._cursor.execute, sql, parameters)
  File "C:\Users\V\Documents\DEV-VINI\github\m00-projeto\venv\Lib\site-packages\aiosqlite\cursor.py", line 32, in _execute
    return await self._conn._execute(fn, *args, **kwargs)
           ^^^^^^^^^^^^^^^^^^^^^^^^^^^^^^^^^^^^^^^^^^^^^^
  File "C:\Users\V\Documents\DEV-VINI\github\m00-projeto\venv\Lib\site-packages\aiosqlite\core.py", line 122, in _execute
    return await future
           ^^^^^^^^^^^^
  File "C:\Users\V\Documents\DEV-VINI\github\m00-projeto\venv\Lib\site-packages\aiosqlite\core.py", line 105, in run
    result = function()
sqlite3.OperationalError: no such table: tasks

The above exception was the direct cause of the following exception:

Traceback (most recent call last):
  File "C:\Users\V\Documents\DEV-VINI\github\m00-projeto\venv\Lib\site-packages\starlette\middleware\errors.py", line 165, in __call__
    await self.app(scope, receive, _send)
  File "C:\Users\V\Documents\DEV-VINI\github\m00-projeto\venv\Lib\site-packages\starlette\middleware\exceptions.py", line 62, in __call__
    await wrap_app_handling_exceptions(self.app, conn)(scope, receive, send)
  File "C:\Users\V\Documents\DEV-VINI\github\m00-projeto\venv\Lib\site-packages\starlette\_exception_handler.py", line 53, in wrapped_app
    raise exc
  File "C:\Users\V\Documents\DEV-VINI\github\m00-projeto\venv\Lib\site-packages\starlette\_exception_handler.py", line 42, in wrapped_app
    await app(scope, receive, sender)
  File "C:\Users\V\Documents\DEV-VINI\github\m00-projeto\venv\Lib\site-packages\starlette\routing.py", line 714, in __call__
    await self.middleware_stack(scope, receive, send)
  File "C:\Users\V\Documents\DEV-VINI\github\m00-projeto\venv\Lib\site-packages\starlette\routing.py", line 734, in app
    await route.handle(scope, receive, send)
  File "C:\Users\V\Documents\DEV-VINI\github\m00-projeto\venv\Lib\site-packages\starlette\routing.py", line 288, in handle
    await self.app(scope, receive, send)
  File "C:\Users\V\Documents\DEV-VINI\github\m00-projeto\venv\Lib\site-packages\starlette\routing.py", line 76, in app
    await wrap_app_handling_exceptions(app, request)(scope, receive, send)
  File "C:\Users\V\Documents\DEV-VINI\github\m00-projeto\venv\Lib\site-packages\starlette\_exception_handler.py", line 53, in wrapped_app
    raise exc
  File "C:\Users\V\Documents\DEV-VINI\github\m00-projeto\venv\Lib\site-packages\starlette\_exception_handler.py", line 42, in wrapped_app
    await app(scope, receive, sender)
  File "C:\Users\V\Documents\DEV-VINI\github\m00-projeto\venv\Lib\site-packages\starlette\routing.py", line 73, in app
    response = await f(request)
               ^^^^^^^^^^^^^^^^
  File "C:\Users\V\Documents\DEV-VINI\github\m00-projeto\venv\Lib\site-packages\fastapi\routing.py", line 301, in app
    raw_response = await run_endpoint_function(
                   ^^^^^^^^^^^^^^^^^^^^^^^^^^^^
    ...<3 lines>...
    )
    ^
  File "C:\Users\V\Documents\DEV-VINI\github\m00-projeto\venv\Lib\site-packages\fastapi\routing.py", line 212, in run_endpoint_function
    return await dependant.call(**values)
           ^^^^^^^^^^^^^^^^^^^^^^^^^^^^^^
  File "C:\Users\V\Documents\DEV-VINI\github\m00-projeto\backend\app\api\tasks.py", line 29, in create_new_task
    task_created = await create_task(db, task)
                   ^^^^^^^^^^^^^^^^^^^^^^^^^^^
  File "C:\Users\V\Documents\DEV-VINI\github\m00-projeto\backend\app\services\task_service.py", line 23, in create_task
    await db.commit()
  File "C:\Users\V\Documents\DEV-VINI\github\m00-projeto\venv\Lib\site-packages\sqlalchemy\ext\asyncio\session.py", line 1014, in commit
    await greenlet_spawn(self.sync_session.commit)
  File "C:\Users\V\Documents\DEV-VINI\github\m00-projeto\venv\Lib\site-packages\sqlalchemy\util\_concurrency_py3k.py", line 203, in greenlet_spawn
    result = context.switch(value)
  File "C:\Users\V\Documents\DEV-VINI\github\m00-projeto\venv\Lib\site-packages\sqlalchemy\orm\session.py", line 2032, in commit
    trans.commit(_to_root=True)
    ~~~~~~~~~~~~^^^^^^^^^^^^^^^
  File "<string>", line 2, in commit
  File "C:\Users\V\Documents\DEV-VINI\github\m00-projeto\venv\Lib\site-packages\sqlalchemy\orm\state_changes.py", line 139, in _go
    ret_value = fn(self, *arg, **kw)
  File "C:\Users\V\Documents\DEV-VINI\github\m00-projeto\venv\Lib\site-packages\sqlalchemy\orm\session.py", line 1313, in commit
    self._prepare_impl()
    ~~~~~~~~~~~~~~~~~~^^
  File "<string>", line 2, in _prepare_impl
  File "C:\Users\V\Documents\DEV-VINI\github\m00-projeto\venv\Lib\site-packages\sqlalchemy\orm\state_changes.py", line 139, in _go
    ret_value = fn(self, *arg, **kw)
  File "C:\Users\V\Documents\DEV-VINI\github\m00-projeto\venv\Lib\site-packages\sqlalchemy\orm\session.py", line 1288, in _prepare_impl
    self.session.flush()
    ~~~~~~~~~~~~~~~~~~^^
  File "C:\Users\V\Documents\DEV-VINI\github\m00-projeto\venv\Lib\site-packages\sqlalchemy\orm\session.py", line 4345, in flush
    self._flush(objects)
    ~~~~~~~~~~~^^^^^^^^^
  File "C:\Users\V\Documents\DEV-VINI\github\m00-projeto\venv\Lib\site-packages\sqlalchemy\orm\session.py", line 4480, in _flush
    with util.safe_reraise():
         ~~~~~~~~~~~~~~~~~^^
  File "C:\Users\V\Documents\DEV-VINI\github\m00-projeto\venv\Lib\site-packages\sqlalchemy\util\langhelpers.py", line 224, in __exit__
    raise exc_value.with_traceback(exc_tb)
  File "C:\Users\V\Documents\DEV-VINI\github\m00-projeto\venv\Lib\site-packages\sqlalchemy\orm\session.py", line 4441, in _flush
    flush_context.execute()
    ~~~~~~~~~~~~~~~~~~~~~^^
  File "C:\Users\V\Documents\DEV-VINI\github\m00-projeto\venv\Lib\site-packages\sqlalchemy\orm\unitofwork.py", line 466, in execute
    rec.execute(self)
    ~~~~~~~~~~~^^^^^^
  File "C:\Users\V\Documents\DEV-VINI\github\m00-projeto\venv\Lib\site-packages\sqlalchemy\orm\unitofwork.py", line 642, in execute
    util.preloaded.orm_persistence.save_obj(
    ~~~~~~~~~~~~~~~~~~~~~~~~~~~~~~~~~~~~~~~^
        self.mapper,
        ^^^^^^^^^^^^
        uow.states_for_mapper_hierarchy(self.mapper, False, False),
        ^^^^^^^^^^^^^^^^^^^^^^^^^^^^^^^^^^^^^^^^^^^^^^^^^^^^^^^^^^^
        uow,
        ^^^^
    )
    ^
  File "C:\Users\V\Documents\DEV-VINI\github\m00-projeto\venv\Lib\site-packages\sqlalchemy\orm\persistence.py", line 93, in save_obj
    _emit_insert_statements(
    ~~~~~~~~~~~~~~~~~~~~~~~^
        base_mapper,
        ^^^^^^^^^^^^
    ...<3 lines>...
        insert,
        ^^^^^^^
    )
    ^
  File "C:\Users\V\Documents\DEV-VINI\github\m00-projeto\venv\Lib\site-packages\sqlalchemy\orm\persistence.py", line 1233, in _emit_insert_statements
    result = connection.execute(
        statement,
        params,
        execution_options=execution_options,
    )
  File "C:\Users\V\Documents\DEV-VINI\github\m00-projeto\venv\Lib\site-packages\sqlalchemy\engine\base.py", line 1415, in execute
    return meth(
        self,
        distilled_parameters,
        execution_options or NO_OPTIONS,
    )
  File "C:\Users\V\Documents\DEV-VINI\github\m00-projeto\venv\Lib\site-packages\sqlalchemy\sql\elements.py", line 523, in _execute_on_connection
    return connection._execute_clauseelement(
           ~~~~~~~~~~~~~~~~~~~~~~~~~~~~~~~~~^
        self, distilled_params, execution_options
        ^^^^^^^^^^^^^^^^^^^^^^^^^^^^^^^^^^^^^^^^^
    )
    ^
  File "C:\Users\V\Documents\DEV-VINI\github\m00-projeto\venv\Lib\site-packages\sqlalchemy\engine\base.py", line 1637, in _execute_clauseelement
    ret = self._execute_context(
        dialect,
    ...<8 lines>...
        cache_hit=cache_hit,
    )
  File "C:\Users\V\Documents\DEV-VINI\github\m00-projeto\venv\Lib\site-packages\sqlalchemy\engine\base.py", line 1842, in _execute_context
    return self._exec_single_context(
           ~~~~~~~~~~~~~~~~~~~~~~~~~^
        dialect, context, statement, parameters
        ^^^^^^^^^^^^^^^^^^^^^^^^^^^^^^^^^^^^^^^
    )
    ^
  File "C:\Users\V\Documents\DEV-VINI\github\m00-projeto\venv\Lib\site-packages\sqlalchemy\engine\base.py", line 1982, in _exec_single_context
    self._handle_dbapi_exception(
    ~~~~~~~~~~~~~~~~~~~~~~~~~~~~^
        e, str_statement, effective_parameters, cursor, context
        ^^^^^^^^^^^^^^^^^^^^^^^^^^^^^^^^^^^^^^^^^^^^^^^^^^^^^^^
    )
    ^
  File "C:\Users\V\Documents\DEV-VINI\github\m00-projeto\venv\Lib\site-packages\sqlalchemy\engine\base.py", line 2351, in _handle_dbapi_exception
    raise sqlalchemy_exception.with_traceback(exc_info[2]) from e
  File "C:\Users\V\Documents\DEV-VINI\github\m00-projeto\venv\Lib\site-packages\sqlalchemy\engine\base.py", line 1963, in _exec_single_context
    self.dialect.do_execute(
    ~~~~~~~~~~~~~~~~~~~~~~~^
        cursor, str_statement, effective_parameters, context
        ^^^^^^^^^^^^^^^^^^^^^^^^^^^^^^^^^^^^^^^^^^^^^^^^^^^^
    )
    ^
  File "C:\Users\V\Documents\DEV-VINI\github\m00-projeto\venv\Lib\site-packages\sqlalchemy\engine\default.py", line 943, in do_execute
    cursor.execute(statement, parameters)
    ~~~~~~~~~~~~~~^^^^^^^^^^^^^^^^^^^^^^^
  File "C:\Users\V\Documents\DEV-VINI\github\m00-projeto\venv\Lib\site-packages\sqlalchemy\dialects\sqlite\aiosqlite.py", line 149, in execute
    self._adapt_connection._handle_exception(error)
    ~~~~~~~~~~~~~~~~~~~~~~~~~~~~~~~~~~~~~~~~^^^^^^^
  File "C:\Users\V\Documents\DEV-VINI\github\m00-projeto\venv\Lib\site-packages\sqlalchemy\dialects\sqlite\aiosqlite.py", line 300, in _handle_exception
    raise error
  File "C:\Users\V\Documents\DEV-VINI\github\m00-projeto\venv\Lib\site-packages\sqlalchemy\dialects\sqlite\aiosqlite.py", line 131, in execute
    self.await_(_cursor.execute(operation, parameters))
    ~~~~~~~~~~~^^^^^^^^^^^^^^^^^^^^^^^^^^^^^^^^^^^^^^^^
  File "C:\Users\V\Documents\DEV-VINI\github\m00-projeto\venv\Lib\site-packages\sqlalchemy\util\_concurrency_py3k.py", line 132, in await_only
    return current.parent.switch(awaitable)  # type: ignore[no-any-return,attr-defined] # noqa: E501
           ~~~~~~~~~~~~~~~~~~~~~^^^^^^^^^^^
  File "C:\Users\V\Documents\DEV-VINI\github\m00-projeto\venv\Lib\site-packages\sqlalchemy\util\_concurrency_py3k.py", line 196, in greenlet_spawn
    value = await result
            ^^^^^^^^^^^^
  File "C:\Users\V\Documents\DEV-VINI\github\m00-projeto\venv\Lib\site-packages\aiosqlite\cursor.py", line 40, in execute
    await self._execute(self._cursor.execute, sql, parameters)
  File "C:\Users\V\Documents\DEV-VINI\github\m00-projeto\venv\Lib\site-packages\aiosqlite\cursor.py", line 32, in _execute
    return await self._conn._execute(fn, *args, **kwargs)
           ^^^^^^^^^^^^^^^^^^^^^^^^^^^^^^^^^^^^^^^^^^^^^^
  File "C:\Users\V\Documents\DEV-VINI\github\m00-projeto\venv\Lib\site-packages\aiosqlite\core.py", line 122, in _execute
    return await future
           ^^^^^^^^^^^^
  File "C:\Users\V\Documents\DEV-VINI\github\m00-projeto\venv\Lib\site-packages\aiosqlite\core.py", line 105, in run
    result = function()
sqlalchemy.exc.OperationalError: (sqlite3.OperationalError) no such table: tasks
[SQL: INSERT INTO tasks (title, description, completed) VALUES (?, ?, ?)]
[parameters: ('Tarefa PUT', 'Desc PUT', 0)]
(Background on this error at: https://sqlalche.me/e/20/e3q8)
2025-06-01 16:31:26,893 | ERROR | m00-backend | Erro inesperado em http://testserver/tasks/: (sqlite3.OperationalError) no such table: tasks
[SQL: INSERT INTO tasks (title, description, completed) VALUES (?, ?, ?)]
[parameters: ('Tarefa DELETE', 'Desc DELETE', 0)]
(Background on this error at: https://sqlalche.me/e/20/e3q8)
Traceback (most recent call last):
  File "C:\Users\V\Documents\DEV-VINI\github\m00-projeto\venv\Lib\site-packages\sqlalchemy\engine\base.py", line 1963, in _exec_single_context
    self.dialect.do_execute(
    ~~~~~~~~~~~~~~~~~~~~~~~^
        cursor, str_statement, effective_parameters, context
        ^^^^^^^^^^^^^^^^^^^^^^^^^^^^^^^^^^^^^^^^^^^^^^^^^^^^
    )
    ^
  File "C:\Users\V\Documents\DEV-VINI\github\m00-projeto\venv\Lib\site-packages\sqlalchemy\engine\default.py", line 943, in do_execute
    cursor.execute(statement, parameters)
    ~~~~~~~~~~~~~~^^^^^^^^^^^^^^^^^^^^^^^
  File "C:\Users\V\Documents\DEV-VINI\github\m00-projeto\venv\Lib\site-packages\sqlalchemy\dialects\sqlite\aiosqlite.py", line 149, in execute
    self._adapt_connection._handle_exception(error)
    ~~~~~~~~~~~~~~~~~~~~~~~~~~~~~~~~~~~~~~~~^^^^^^^
  File "C:\Users\V\Documents\DEV-VINI\github\m00-projeto\venv\Lib\site-packages\sqlalchemy\dialects\sqlite\aiosqlite.py", line 300, in _handle_exception
    raise error
  File "C:\Users\V\Documents\DEV-VINI\github\m00-projeto\venv\Lib\site-packages\sqlalchemy\dialects\sqlite\aiosqlite.py", line 131, in execute
    self.await_(_cursor.execute(operation, parameters))
    ~~~~~~~~~~~^^^^^^^^^^^^^^^^^^^^^^^^^^^^^^^^^^^^^^^^
  File "C:\Users\V\Documents\DEV-VINI\github\m00-projeto\venv\Lib\site-packages\sqlalchemy\util\_concurrency_py3k.py", line 132, in await_only
    return current.parent.switch(awaitable)  # type: ignore[no-any-return,attr-defined] # noqa: E501
           ~~~~~~~~~~~~~~~~~~~~~^^^^^^^^^^^
  File "C:\Users\V\Documents\DEV-VINI\github\m00-projeto\venv\Lib\site-packages\sqlalchemy\util\_concurrency_py3k.py", line 196, in greenlet_spawn
    value = await result
            ^^^^^^^^^^^^
  File "C:\Users\V\Documents\DEV-VINI\github\m00-projeto\venv\Lib\site-packages\aiosqlite\cursor.py", line 40, in execute
    await self._execute(self._cursor.execute, sql, parameters)
  File "C:\Users\V\Documents\DEV-VINI\github\m00-projeto\venv\Lib\site-packages\aiosqlite\cursor.py", line 32, in _execute
    return await self._conn._execute(fn, *args, **kwargs)
           ^^^^^^^^^^^^^^^^^^^^^^^^^^^^^^^^^^^^^^^^^^^^^^
  File "C:\Users\V\Documents\DEV-VINI\github\m00-projeto\venv\Lib\site-packages\aiosqlite\core.py", line 122, in _execute
    return await future
           ^^^^^^^^^^^^
  File "C:\Users\V\Documents\DEV-VINI\github\m00-projeto\venv\Lib\site-packages\aiosqlite\core.py", line 105, in run
    result = function()
sqlite3.OperationalError: no such table: tasks

The above exception was the direct cause of the following exception:

Traceback (most recent call last):
  File "C:\Users\V\Documents\DEV-VINI\github\m00-projeto\venv\Lib\site-packages\starlette\middleware\errors.py", line 165, in __call__
    await self.app(scope, receive, _send)
  File "C:\Users\V\Documents\DEV-VINI\github\m00-projeto\venv\Lib\site-packages\starlette\middleware\exceptions.py", line 62, in __call__
    await wrap_app_handling_exceptions(self.app, conn)(scope, receive, send)
  File "C:\Users\V\Documents\DEV-VINI\github\m00-projeto\venv\Lib\site-packages\starlette\_exception_handler.py", line 53, in wrapped_app
    raise exc
  File "C:\Users\V\Documents\DEV-VINI\github\m00-projeto\venv\Lib\site-packages\starlette\_exception_handler.py", line 42, in wrapped_app
    await app(scope, receive, sender)
  File "C:\Users\V\Documents\DEV-VINI\github\m00-projeto\venv\Lib\site-packages\starlette\routing.py", line 714, in __call__
    await self.middleware_stack(scope, receive, send)
  File "C:\Users\V\Documents\DEV-VINI\github\m00-projeto\venv\Lib\site-packages\starlette\routing.py", line 734, in app
    await route.handle(scope, receive, send)
  File "C:\Users\V\Documents\DEV-VINI\github\m00-projeto\venv\Lib\site-packages\starlette\routing.py", line 288, in handle
    await self.app(scope, receive, send)
  File "C:\Users\V\Documents\DEV-VINI\github\m00-projeto\venv\Lib\site-packages\starlette\routing.py", line 76, in app
    await wrap_app_handling_exceptions(app, request)(scope, receive, send)
  File "C:\Users\V\Documents\DEV-VINI\github\m00-projeto\venv\Lib\site-packages\starlette\_exception_handler.py", line 53, in wrapped_app
    raise exc
  File "C:\Users\V\Documents\DEV-VINI\github\m00-projeto\venv\Lib\site-packages\starlette\_exception_handler.py", line 42, in wrapped_app
    await app(scope, receive, sender)
  File "C:\Users\V\Documents\DEV-VINI\github\m00-projeto\venv\Lib\site-packages\starlette\routing.py", line 73, in app
    response = await f(request)
               ^^^^^^^^^^^^^^^^
  File "C:\Users\V\Documents\DEV-VINI\github\m00-projeto\venv\Lib\site-packages\fastapi\routing.py", line 301, in app
    raw_response = await run_endpoint_function(
                   ^^^^^^^^^^^^^^^^^^^^^^^^^^^^
    ...<3 lines>...
    )
    ^
  File "C:\Users\V\Documents\DEV-VINI\github\m00-projeto\venv\Lib\site-packages\fastapi\routing.py", line 212, in run_endpoint_function
    return await dependant.call(**values)
           ^^^^^^^^^^^^^^^^^^^^^^^^^^^^^^
  File "C:\Users\V\Documents\DEV-VINI\github\m00-projeto\backend\app\api\tasks.py", line 29, in create_new_task
    task_created = await create_task(db, task)
                   ^^^^^^^^^^^^^^^^^^^^^^^^^^^
  File "C:\Users\V\Documents\DEV-VINI\github\m00-projeto\backend\app\services\task_service.py", line 23, in create_task
    await db.commit()
  File "C:\Users\V\Documents\DEV-VINI\github\m00-projeto\venv\Lib\site-packages\sqlalchemy\ext\asyncio\session.py", line 1014, in commit
    await greenlet_spawn(self.sync_session.commit)
  File "C:\Users\V\Documents\DEV-VINI\github\m00-projeto\venv\Lib\site-packages\sqlalchemy\util\_concurrency_py3k.py", line 203, in greenlet_spawn
    result = context.switch(value)
  File "C:\Users\V\Documents\DEV-VINI\github\m00-projeto\venv\Lib\site-packages\sqlalchemy\orm\session.py", line 2032, in commit
    trans.commit(_to_root=True)
    ~~~~~~~~~~~~^^^^^^^^^^^^^^^
  File "<string>", line 2, in commit
  File "C:\Users\V\Documents\DEV-VINI\github\m00-projeto\venv\Lib\site-packages\sqlalchemy\orm\state_changes.py", line 139, in _go
    ret_value = fn(self, *arg, **kw)
  File "C:\Users\V\Documents\DEV-VINI\github\m00-projeto\venv\Lib\site-packages\sqlalchemy\orm\session.py", line 1313, in commit
    self._prepare_impl()
    ~~~~~~~~~~~~~~~~~~^^
  File "<string>", line 2, in _prepare_impl
  File "C:\Users\V\Documents\DEV-VINI\github\m00-projeto\venv\Lib\site-packages\sqlalchemy\orm\state_changes.py", line 139, in _go
    ret_value = fn(self, *arg, **kw)
  File "C:\Users\V\Documents\DEV-VINI\github\m00-projeto\venv\Lib\site-packages\sqlalchemy\orm\session.py", line 1288, in _prepare_impl
    self.session.flush()
    ~~~~~~~~~~~~~~~~~~^^
  File "C:\Users\V\Documents\DEV-VINI\github\m00-projeto\venv\Lib\site-packages\sqlalchemy\orm\session.py", line 4345, in flush
    self._flush(objects)
    ~~~~~~~~~~~^^^^^^^^^
  File "C:\Users\V\Documents\DEV-VINI\github\m00-projeto\venv\Lib\site-packages\sqlalchemy\orm\session.py", line 4480, in _flush
    with util.safe_reraise():
         ~~~~~~~~~~~~~~~~~^^
  File "C:\Users\V\Documents\DEV-VINI\github\m00-projeto\venv\Lib\site-packages\sqlalchemy\util\langhelpers.py", line 224, in __exit__
    raise exc_value.with_traceback(exc_tb)
  File "C:\Users\V\Documents\DEV-VINI\github\m00-projeto\venv\Lib\site-packages\sqlalchemy\orm\session.py", line 4441, in _flush
    flush_context.execute()
    ~~~~~~~~~~~~~~~~~~~~~^^
  File "C:\Users\V\Documents\DEV-VINI\github\m00-projeto\venv\Lib\site-packages\sqlalchemy\orm\unitofwork.py", line 466, in execute
    rec.execute(self)
    ~~~~~~~~~~~^^^^^^
  File "C:\Users\V\Documents\DEV-VINI\github\m00-projeto\venv\Lib\site-packages\sqlalchemy\orm\unitofwork.py", line 642, in execute
    util.preloaded.orm_persistence.save_obj(
    ~~~~~~~~~~~~~~~~~~~~~~~~~~~~~~~~~~~~~~~^
        self.mapper,
        ^^^^^^^^^^^^
        uow.states_for_mapper_hierarchy(self.mapper, False, False),
        ^^^^^^^^^^^^^^^^^^^^^^^^^^^^^^^^^^^^^^^^^^^^^^^^^^^^^^^^^^^
        uow,
        ^^^^
    )
    ^
  File "C:\Users\V\Documents\DEV-VINI\github\m00-projeto\venv\Lib\site-packages\sqlalchemy\orm\persistence.py", line 93, in save_obj
    _emit_insert_statements(
    ~~~~~~~~~~~~~~~~~~~~~~~^
        base_mapper,
        ^^^^^^^^^^^^
    ...<3 lines>...
        insert,
        ^^^^^^^
    )
    ^
  File "C:\Users\V\Documents\DEV-VINI\github\m00-projeto\venv\Lib\site-packages\sqlalchemy\orm\persistence.py", line 1233, in _emit_insert_statements
    result = connection.execute(
        statement,
        params,
        execution_options=execution_options,
    )
  File "C:\Users\V\Documents\DEV-VINI\github\m00-projeto\venv\Lib\site-packages\sqlalchemy\engine\base.py", line 1415, in execute
    return meth(
        self,
        distilled_parameters,
        execution_options or NO_OPTIONS,
    )
  File "C:\Users\V\Documents\DEV-VINI\github\m00-projeto\venv\Lib\site-packages\sqlalchemy\sql\elements.py", line 523, in _execute_on_connection
    return connection._execute_clauseelement(
           ~~~~~~~~~~~~~~~~~~~~~~~~~~~~~~~~~^
        self, distilled_params, execution_options
        ^^^^^^^^^^^^^^^^^^^^^^^^^^^^^^^^^^^^^^^^^
    )
    ^
  File "C:\Users\V\Documents\DEV-VINI\github\m00-projeto\venv\Lib\site-packages\sqlalchemy\engine\base.py", line 1637, in _execute_clauseelement
    ret = self._execute_context(
        dialect,
    ...<8 lines>...
        cache_hit=cache_hit,
    )
  File "C:\Users\V\Documents\DEV-VINI\github\m00-projeto\venv\Lib\site-packages\sqlalchemy\engine\base.py", line 1842, in _execute_context
    return self._exec_single_context(
           ~~~~~~~~~~~~~~~~~~~~~~~~~^
        dialect, context, statement, parameters
        ^^^^^^^^^^^^^^^^^^^^^^^^^^^^^^^^^^^^^^^
    )
    ^
  File "C:\Users\V\Documents\DEV-VINI\github\m00-projeto\venv\Lib\site-packages\sqlalchemy\engine\base.py", line 1982, in _exec_single_context
    self._handle_dbapi_exception(
    ~~~~~~~~~~~~~~~~~~~~~~~~~~~~^
        e, str_statement, effective_parameters, cursor, context
        ^^^^^^^^^^^^^^^^^^^^^^^^^^^^^^^^^^^^^^^^^^^^^^^^^^^^^^^
    )
    ^
  File "C:\Users\V\Documents\DEV-VINI\github\m00-projeto\venv\Lib\site-packages\sqlalchemy\engine\base.py", line 2351, in _handle_dbapi_exception
    raise sqlalchemy_exception.with_traceback(exc_info[2]) from e
  File "C:\Users\V\Documents\DEV-VINI\github\m00-projeto\venv\Lib\site-packages\sqlalchemy\engine\base.py", line 1963, in _exec_single_context
    self.dialect.do_execute(
    ~~~~~~~~~~~~~~~~~~~~~~~^
        cursor, str_statement, effective_parameters, context
        ^^^^^^^^^^^^^^^^^^^^^^^^^^^^^^^^^^^^^^^^^^^^^^^^^^^^
    )
    ^
  File "C:\Users\V\Documents\DEV-VINI\github\m00-projeto\venv\Lib\site-packages\sqlalchemy\engine\default.py", line 943, in do_execute
    cursor.execute(statement, parameters)
    ~~~~~~~~~~~~~~^^^^^^^^^^^^^^^^^^^^^^^
  File "C:\Users\V\Documents\DEV-VINI\github\m00-projeto\venv\Lib\site-packages\sqlalchemy\dialects\sqlite\aiosqlite.py", line 149, in execute
    self._adapt_connection._handle_exception(error)
    ~~~~~~~~~~~~~~~~~~~~~~~~~~~~~~~~~~~~~~~~^^^^^^^
  File "C:\Users\V\Documents\DEV-VINI\github\m00-projeto\venv\Lib\site-packages\sqlalchemy\dialects\sqlite\aiosqlite.py", line 300, in _handle_exception
    raise error
  File "C:\Users\V\Documents\DEV-VINI\github\m00-projeto\venv\Lib\site-packages\sqlalchemy\dialects\sqlite\aiosqlite.py", line 131, in execute
    self.await_(_cursor.execute(operation, parameters))
    ~~~~~~~~~~~^^^^^^^^^^^^^^^^^^^^^^^^^^^^^^^^^^^^^^^^
  File "C:\Users\V\Documents\DEV-VINI\github\m00-projeto\venv\Lib\site-packages\sqlalchemy\util\_concurrency_py3k.py", line 132, in await_only
    return current.parent.switch(awaitable)  # type: ignore[no-any-return,attr-defined] # noqa: E501
           ~~~~~~~~~~~~~~~~~~~~~^^^^^^^^^^^
  File "C:\Users\V\Documents\DEV-VINI\github\m00-projeto\venv\Lib\site-packages\sqlalchemy\util\_concurrency_py3k.py", line 196, in greenlet_spawn
    value = await result
            ^^^^^^^^^^^^
  File "C:\Users\V\Documents\DEV-VINI\github\m00-projeto\venv\Lib\site-packages\aiosqlite\cursor.py", line 40, in execute
    await self._execute(self._cursor.execute, sql, parameters)
  File "C:\Users\V\Documents\DEV-VINI\github\m00-projeto\venv\Lib\site-packages\aiosqlite\cursor.py", line 32, in _execute
    return await self._conn._execute(fn, *args, **kwargs)
           ^^^^^^^^^^^^^^^^^^^^^^^^^^^^^^^^^^^^^^^^^^^^^^
  File "C:\Users\V\Documents\DEV-VINI\github\m00-projeto\venv\Lib\site-packages\aiosqlite\core.py", line 122, in _execute
    return await future
           ^^^^^^^^^^^^
  File "C:\Users\V\Documents\DEV-VINI\github\m00-projeto\venv\Lib\site-packages\aiosqlite\core.py", line 105, in run
    result = function()
sqlalchemy.exc.OperationalError: (sqlite3.OperationalError) no such table: tasks
[SQL: INSERT INTO tasks (title, description, completed) VALUES (?, ?, ?)]
[parameters: ('Tarefa DELETE', 'Desc DELETE', 0)]
(Background on this error at: https://sqlalche.me/e/20/e3q8)
2025-06-01 16:31:41,125 | INFO | m00-backend | Iniciando m00-backend
2025-06-01 16:31:41,125 | INFO | m00-backend | === Teste de gravação em arquivo de log ===
2025-06-01 16:31:41,319 | INFO | m00-backend | Rota raiz acessada
2025-06-01 16:31:41,358 | ERROR | m00-backend | Erro inesperado em http://testserver/tasks/: (sqlite3.OperationalError) no such table: tasks
[SQL: SELECT tasks.id, tasks.title, tasks.description, tasks.completed 
FROM tasks]
(Background on this error at: https://sqlalche.me/e/20/e3q8)
Traceback (most recent call last):
  File "C:\Users\V\Documents\DEV-VINI\github\m00-projeto\venv\Lib\site-packages\sqlalchemy\engine\base.py", line 1963, in _exec_single_context
    self.dialect.do_execute(
    ~~~~~~~~~~~~~~~~~~~~~~~^
        cursor, str_statement, effective_parameters, context
        ^^^^^^^^^^^^^^^^^^^^^^^^^^^^^^^^^^^^^^^^^^^^^^^^^^^^
    )
    ^
  File "C:\Users\V\Documents\DEV-VINI\github\m00-projeto\venv\Lib\site-packages\sqlalchemy\engine\default.py", line 943, in do_execute
    cursor.execute(statement, parameters)
    ~~~~~~~~~~~~~~^^^^^^^^^^^^^^^^^^^^^^^
  File "C:\Users\V\Documents\DEV-VINI\github\m00-projeto\venv\Lib\site-packages\sqlalchemy\dialects\sqlite\aiosqlite.py", line 149, in execute
    self._adapt_connection._handle_exception(error)
    ~~~~~~~~~~~~~~~~~~~~~~~~~~~~~~~~~~~~~~~~^^^^^^^
  File "C:\Users\V\Documents\DEV-VINI\github\m00-projeto\venv\Lib\site-packages\sqlalchemy\dialects\sqlite\aiosqlite.py", line 300, in _handle_exception
    raise error
  File "C:\Users\V\Documents\DEV-VINI\github\m00-projeto\venv\Lib\site-packages\sqlalchemy\dialects\sqlite\aiosqlite.py", line 131, in execute
    self.await_(_cursor.execute(operation, parameters))
    ~~~~~~~~~~~^^^^^^^^^^^^^^^^^^^^^^^^^^^^^^^^^^^^^^^^
  File "C:\Users\V\Documents\DEV-VINI\github\m00-projeto\venv\Lib\site-packages\sqlalchemy\util\_concurrency_py3k.py", line 132, in await_only
    return current.parent.switch(awaitable)  # type: ignore[no-any-return,attr-defined] # noqa: E501
           ~~~~~~~~~~~~~~~~~~~~~^^^^^^^^^^^
  File "C:\Users\V\Documents\DEV-VINI\github\m00-projeto\venv\Lib\site-packages\sqlalchemy\util\_concurrency_py3k.py", line 196, in greenlet_spawn
    value = await result
            ^^^^^^^^^^^^
  File "C:\Users\V\Documents\DEV-VINI\github\m00-projeto\venv\Lib\site-packages\aiosqlite\cursor.py", line 40, in execute
    await self._execute(self._cursor.execute, sql, parameters)
  File "C:\Users\V\Documents\DEV-VINI\github\m00-projeto\venv\Lib\site-packages\aiosqlite\cursor.py", line 32, in _execute
    return await self._conn._execute(fn, *args, **kwargs)
           ^^^^^^^^^^^^^^^^^^^^^^^^^^^^^^^^^^^^^^^^^^^^^^
  File "C:\Users\V\Documents\DEV-VINI\github\m00-projeto\venv\Lib\site-packages\aiosqlite\core.py", line 122, in _execute
    return await future
           ^^^^^^^^^^^^
  File "C:\Users\V\Documents\DEV-VINI\github\m00-projeto\venv\Lib\site-packages\aiosqlite\core.py", line 105, in run
    result = function()
sqlite3.OperationalError: no such table: tasks

The above exception was the direct cause of the following exception:

Traceback (most recent call last):
  File "C:\Users\V\Documents\DEV-VINI\github\m00-projeto\venv\Lib\site-packages\starlette\middleware\errors.py", line 165, in __call__
    await self.app(scope, receive, _send)
  File "C:\Users\V\Documents\DEV-VINI\github\m00-projeto\venv\Lib\site-packages\starlette\middleware\exceptions.py", line 62, in __call__
    await wrap_app_handling_exceptions(self.app, conn)(scope, receive, send)
  File "C:\Users\V\Documents\DEV-VINI\github\m00-projeto\venv\Lib\site-packages\starlette\_exception_handler.py", line 53, in wrapped_app
    raise exc
  File "C:\Users\V\Documents\DEV-VINI\github\m00-projeto\venv\Lib\site-packages\starlette\_exception_handler.py", line 42, in wrapped_app
    await app(scope, receive, sender)
  File "C:\Users\V\Documents\DEV-VINI\github\m00-projeto\venv\Lib\site-packages\starlette\routing.py", line 714, in __call__
    await self.middleware_stack(scope, receive, send)
  File "C:\Users\V\Documents\DEV-VINI\github\m00-projeto\venv\Lib\site-packages\starlette\routing.py", line 734, in app
    await route.handle(scope, receive, send)
  File "C:\Users\V\Documents\DEV-VINI\github\m00-projeto\venv\Lib\site-packages\starlette\routing.py", line 288, in handle
    await self.app(scope, receive, send)
  File "C:\Users\V\Documents\DEV-VINI\github\m00-projeto\venv\Lib\site-packages\starlette\routing.py", line 76, in app
    await wrap_app_handling_exceptions(app, request)(scope, receive, send)
  File "C:\Users\V\Documents\DEV-VINI\github\m00-projeto\venv\Lib\site-packages\starlette\_exception_handler.py", line 53, in wrapped_app
    raise exc
  File "C:\Users\V\Documents\DEV-VINI\github\m00-projeto\venv\Lib\site-packages\starlette\_exception_handler.py", line 42, in wrapped_app
    await app(scope, receive, sender)
  File "C:\Users\V\Documents\DEV-VINI\github\m00-projeto\venv\Lib\site-packages\starlette\routing.py", line 73, in app
    response = await f(request)
               ^^^^^^^^^^^^^^^^
  File "C:\Users\V\Documents\DEV-VINI\github\m00-projeto\venv\Lib\site-packages\fastapi\routing.py", line 301, in app
    raw_response = await run_endpoint_function(
                   ^^^^^^^^^^^^^^^^^^^^^^^^^^^^
    ...<3 lines>...
    )
    ^
  File "C:\Users\V\Documents\DEV-VINI\github\m00-projeto\venv\Lib\site-packages\fastapi\routing.py", line 212, in run_endpoint_function
    return await dependant.call(**values)
           ^^^^^^^^^^^^^^^^^^^^^^^^^^^^^^
  File "C:\Users\V\Documents\DEV-VINI\github\m00-projeto\backend\app\api\tasks.py", line 38, in get_tasks
    result = await db.execute(select(TaskModel))
             ^^^^^^^^^^^^^^^^^^^^^^^^^^^^^^^^^^^
  File "C:\Users\V\Documents\DEV-VINI\github\m00-projeto\venv\Lib\site-packages\sqlalchemy\ext\asyncio\session.py", line 463, in execute
    result = await greenlet_spawn(
             ^^^^^^^^^^^^^^^^^^^^^
    ...<6 lines>...
    )
    ^
  File "C:\Users\V\Documents\DEV-VINI\github\m00-projeto\venv\Lib\site-packages\sqlalchemy\util\_concurrency_py3k.py", line 201, in greenlet_spawn
    result = context.throw(*sys.exc_info())
  File "C:\Users\V\Documents\DEV-VINI\github\m00-projeto\venv\Lib\site-packages\sqlalchemy\orm\session.py", line 2365, in execute
    return self._execute_internal(
           ~~~~~~~~~~~~~~~~~~~~~~^
        statement,
        ^^^^^^^^^^
    ...<4 lines>...
        _add_event=_add_event,
        ^^^^^^^^^^^^^^^^^^^^^^
    )
    ^
  File "C:\Users\V\Documents\DEV-VINI\github\m00-projeto\venv\Lib\site-packages\sqlalchemy\orm\session.py", line 2251, in _execute_internal
    result: Result[Any] = compile_state_cls.orm_execute_statement(
                          ~~~~~~~~~~~~~~~~~~~~~~~~~~~~~~~~~~~~~~~^
        self,
        ^^^^^
    ...<4 lines>...
        conn,
        ^^^^^
    )
    ^
  File "C:\Users\V\Documents\DEV-VINI\github\m00-projeto\venv\Lib\site-packages\sqlalchemy\orm\context.py", line 306, in orm_execute_statement
    result = conn.execute(
        statement, params or {}, execution_options=execution_options
    )
  File "C:\Users\V\Documents\DEV-VINI\github\m00-projeto\venv\Lib\site-packages\sqlalchemy\engine\base.py", line 1415, in execute
    return meth(
        self,
        distilled_parameters,
        execution_options or NO_OPTIONS,
    )
  File "C:\Users\V\Documents\DEV-VINI\github\m00-projeto\venv\Lib\site-packages\sqlalchemy\sql\elements.py", line 523, in _execute_on_connection
    return connection._execute_clauseelement(
           ~~~~~~~~~~~~~~~~~~~~~~~~~~~~~~~~~^
        self, distilled_params, execution_options
        ^^^^^^^^^^^^^^^^^^^^^^^^^^^^^^^^^^^^^^^^^
    )
    ^
  File "C:\Users\V\Documents\DEV-VINI\github\m00-projeto\venv\Lib\site-packages\sqlalchemy\engine\base.py", line 1637, in _execute_clauseelement
    ret = self._execute_context(
        dialect,
    ...<8 lines>...
        cache_hit=cache_hit,
    )
  File "C:\Users\V\Documents\DEV-VINI\github\m00-projeto\venv\Lib\site-packages\sqlalchemy\engine\base.py", line 1842, in _execute_context
    return self._exec_single_context(
           ~~~~~~~~~~~~~~~~~~~~~~~~~^
        dialect, context, statement, parameters
        ^^^^^^^^^^^^^^^^^^^^^^^^^^^^^^^^^^^^^^^
    )
    ^
  File "C:\Users\V\Documents\DEV-VINI\github\m00-projeto\venv\Lib\site-packages\sqlalchemy\engine\base.py", line 1982, in _exec_single_context
    self._handle_dbapi_exception(
    ~~~~~~~~~~~~~~~~~~~~~~~~~~~~^
        e, str_statement, effective_parameters, cursor, context
        ^^^^^^^^^^^^^^^^^^^^^^^^^^^^^^^^^^^^^^^^^^^^^^^^^^^^^^^
    )
    ^
  File "C:\Users\V\Documents\DEV-VINI\github\m00-projeto\venv\Lib\site-packages\sqlalchemy\engine\base.py", line 2351, in _handle_dbapi_exception
    raise sqlalchemy_exception.with_traceback(exc_info[2]) from e
  File "C:\Users\V\Documents\DEV-VINI\github\m00-projeto\venv\Lib\site-packages\sqlalchemy\engine\base.py", line 1963, in _exec_single_context
    self.dialect.do_execute(
    ~~~~~~~~~~~~~~~~~~~~~~~^
        cursor, str_statement, effective_parameters, context
        ^^^^^^^^^^^^^^^^^^^^^^^^^^^^^^^^^^^^^^^^^^^^^^^^^^^^
    )
    ^
  File "C:\Users\V\Documents\DEV-VINI\github\m00-projeto\venv\Lib\site-packages\sqlalchemy\engine\default.py", line 943, in do_execute
    cursor.execute(statement, parameters)
    ~~~~~~~~~~~~~~^^^^^^^^^^^^^^^^^^^^^^^
  File "C:\Users\V\Documents\DEV-VINI\github\m00-projeto\venv\Lib\site-packages\sqlalchemy\dialects\sqlite\aiosqlite.py", line 149, in execute
    self._adapt_connection._handle_exception(error)
    ~~~~~~~~~~~~~~~~~~~~~~~~~~~~~~~~~~~~~~~~^^^^^^^
  File "C:\Users\V\Documents\DEV-VINI\github\m00-projeto\venv\Lib\site-packages\sqlalchemy\dialects\sqlite\aiosqlite.py", line 300, in _handle_exception
    raise error
  File "C:\Users\V\Documents\DEV-VINI\github\m00-projeto\venv\Lib\site-packages\sqlalchemy\dialects\sqlite\aiosqlite.py", line 131, in execute
    self.await_(_cursor.execute(operation, parameters))
    ~~~~~~~~~~~^^^^^^^^^^^^^^^^^^^^^^^^^^^^^^^^^^^^^^^^
  File "C:\Users\V\Documents\DEV-VINI\github\m00-projeto\venv\Lib\site-packages\sqlalchemy\util\_concurrency_py3k.py", line 132, in await_only
    return current.parent.switch(awaitable)  # type: ignore[no-any-return,attr-defined] # noqa: E501
           ~~~~~~~~~~~~~~~~~~~~~^^^^^^^^^^^
  File "C:\Users\V\Documents\DEV-VINI\github\m00-projeto\venv\Lib\site-packages\sqlalchemy\util\_concurrency_py3k.py", line 196, in greenlet_spawn
    value = await result
            ^^^^^^^^^^^^
  File "C:\Users\V\Documents\DEV-VINI\github\m00-projeto\venv\Lib\site-packages\aiosqlite\cursor.py", line 40, in execute
    await self._execute(self._cursor.execute, sql, parameters)
  File "C:\Users\V\Documents\DEV-VINI\github\m00-projeto\venv\Lib\site-packages\aiosqlite\cursor.py", line 32, in _execute
    return await self._conn._execute(fn, *args, **kwargs)
           ^^^^^^^^^^^^^^^^^^^^^^^^^^^^^^^^^^^^^^^^^^^^^^
  File "C:\Users\V\Documents\DEV-VINI\github\m00-projeto\venv\Lib\site-packages\aiosqlite\core.py", line 122, in _execute
    return await future
           ^^^^^^^^^^^^
  File "C:\Users\V\Documents\DEV-VINI\github\m00-projeto\venv\Lib\site-packages\aiosqlite\core.py", line 105, in run
    result = function()
sqlalchemy.exc.OperationalError: (sqlite3.OperationalError) no such table: tasks
[SQL: SELECT tasks.id, tasks.title, tasks.description, tasks.completed 
FROM tasks]
(Background on this error at: https://sqlalche.me/e/20/e3q8)
2025-06-01 16:31:41,793 | ERROR | m00-backend | Erro inesperado em http://testserver/tasks/: (sqlite3.OperationalError) no such table: tasks
[SQL: INSERT INTO tasks (title, description, completed) VALUES (?, ?, ?)]
[parameters: ('Nova Tarefa', 'Descrição de teste', 0)]
(Background on this error at: https://sqlalche.me/e/20/e3q8)
Traceback (most recent call last):
  File "C:\Users\V\Documents\DEV-VINI\github\m00-projeto\venv\Lib\site-packages\sqlalchemy\engine\base.py", line 1963, in _exec_single_context
    self.dialect.do_execute(
    ~~~~~~~~~~~~~~~~~~~~~~~^
        cursor, str_statement, effective_parameters, context
        ^^^^^^^^^^^^^^^^^^^^^^^^^^^^^^^^^^^^^^^^^^^^^^^^^^^^
    )
    ^
  File "C:\Users\V\Documents\DEV-VINI\github\m00-projeto\venv\Lib\site-packages\sqlalchemy\engine\default.py", line 943, in do_execute
    cursor.execute(statement, parameters)
    ~~~~~~~~~~~~~~^^^^^^^^^^^^^^^^^^^^^^^
  File "C:\Users\V\Documents\DEV-VINI\github\m00-projeto\venv\Lib\site-packages\sqlalchemy\dialects\sqlite\aiosqlite.py", line 149, in execute
    self._adapt_connection._handle_exception(error)
    ~~~~~~~~~~~~~~~~~~~~~~~~~~~~~~~~~~~~~~~~^^^^^^^
  File "C:\Users\V\Documents\DEV-VINI\github\m00-projeto\venv\Lib\site-packages\sqlalchemy\dialects\sqlite\aiosqlite.py", line 300, in _handle_exception
    raise error
  File "C:\Users\V\Documents\DEV-VINI\github\m00-projeto\venv\Lib\site-packages\sqlalchemy\dialects\sqlite\aiosqlite.py", line 131, in execute
    self.await_(_cursor.execute(operation, parameters))
    ~~~~~~~~~~~^^^^^^^^^^^^^^^^^^^^^^^^^^^^^^^^^^^^^^^^
  File "C:\Users\V\Documents\DEV-VINI\github\m00-projeto\venv\Lib\site-packages\sqlalchemy\util\_concurrency_py3k.py", line 132, in await_only
    return current.parent.switch(awaitable)  # type: ignore[no-any-return,attr-defined] # noqa: E501
           ~~~~~~~~~~~~~~~~~~~~~^^^^^^^^^^^
  File "C:\Users\V\Documents\DEV-VINI\github\m00-projeto\venv\Lib\site-packages\sqlalchemy\util\_concurrency_py3k.py", line 196, in greenlet_spawn
    value = await result
            ^^^^^^^^^^^^
  File "C:\Users\V\Documents\DEV-VINI\github\m00-projeto\venv\Lib\site-packages\aiosqlite\cursor.py", line 40, in execute
    await self._execute(self._cursor.execute, sql, parameters)
  File "C:\Users\V\Documents\DEV-VINI\github\m00-projeto\venv\Lib\site-packages\aiosqlite\cursor.py", line 32, in _execute
    return await self._conn._execute(fn, *args, **kwargs)
           ^^^^^^^^^^^^^^^^^^^^^^^^^^^^^^^^^^^^^^^^^^^^^^
  File "C:\Users\V\Documents\DEV-VINI\github\m00-projeto\venv\Lib\site-packages\aiosqlite\core.py", line 122, in _execute
    return await future
           ^^^^^^^^^^^^
  File "C:\Users\V\Documents\DEV-VINI\github\m00-projeto\venv\Lib\site-packages\aiosqlite\core.py", line 105, in run
    result = function()
sqlite3.OperationalError: no such table: tasks

The above exception was the direct cause of the following exception:

Traceback (most recent call last):
  File "C:\Users\V\Documents\DEV-VINI\github\m00-projeto\venv\Lib\site-packages\starlette\middleware\errors.py", line 165, in __call__
    await self.app(scope, receive, _send)
  File "C:\Users\V\Documents\DEV-VINI\github\m00-projeto\venv\Lib\site-packages\starlette\middleware\exceptions.py", line 62, in __call__
    await wrap_app_handling_exceptions(self.app, conn)(scope, receive, send)
  File "C:\Users\V\Documents\DEV-VINI\github\m00-projeto\venv\Lib\site-packages\starlette\_exception_handler.py", line 53, in wrapped_app
    raise exc
  File "C:\Users\V\Documents\DEV-VINI\github\m00-projeto\venv\Lib\site-packages\starlette\_exception_handler.py", line 42, in wrapped_app
    await app(scope, receive, sender)
  File "C:\Users\V\Documents\DEV-VINI\github\m00-projeto\venv\Lib\site-packages\starlette\routing.py", line 714, in __call__
    await self.middleware_stack(scope, receive, send)
  File "C:\Users\V\Documents\DEV-VINI\github\m00-projeto\venv\Lib\site-packages\starlette\routing.py", line 734, in app
    await route.handle(scope, receive, send)
  File "C:\Users\V\Documents\DEV-VINI\github\m00-projeto\venv\Lib\site-packages\starlette\routing.py", line 288, in handle
    await self.app(scope, receive, send)
  File "C:\Users\V\Documents\DEV-VINI\github\m00-projeto\venv\Lib\site-packages\starlette\routing.py", line 76, in app
    await wrap_app_handling_exceptions(app, request)(scope, receive, send)
  File "C:\Users\V\Documents\DEV-VINI\github\m00-projeto\venv\Lib\site-packages\starlette\_exception_handler.py", line 53, in wrapped_app
    raise exc
  File "C:\Users\V\Documents\DEV-VINI\github\m00-projeto\venv\Lib\site-packages\starlette\_exception_handler.py", line 42, in wrapped_app
    await app(scope, receive, sender)
  File "C:\Users\V\Documents\DEV-VINI\github\m00-projeto\venv\Lib\site-packages\starlette\routing.py", line 73, in app
    response = await f(request)
               ^^^^^^^^^^^^^^^^
  File "C:\Users\V\Documents\DEV-VINI\github\m00-projeto\venv\Lib\site-packages\fastapi\routing.py", line 301, in app
    raw_response = await run_endpoint_function(
                   ^^^^^^^^^^^^^^^^^^^^^^^^^^^^
    ...<3 lines>...
    )
    ^
  File "C:\Users\V\Documents\DEV-VINI\github\m00-projeto\venv\Lib\site-packages\fastapi\routing.py", line 212, in run_endpoint_function
    return await dependant.call(**values)
           ^^^^^^^^^^^^^^^^^^^^^^^^^^^^^^
  File "C:\Users\V\Documents\DEV-VINI\github\m00-projeto\backend\app\api\tasks.py", line 29, in create_new_task
    task_created = await create_task(db, task)
                   ^^^^^^^^^^^^^^^^^^^^^^^^^^^
  File "C:\Users\V\Documents\DEV-VINI\github\m00-projeto\backend\app\services\task_service.py", line 23, in create_task
    await db.commit()
  File "C:\Users\V\Documents\DEV-VINI\github\m00-projeto\venv\Lib\site-packages\sqlalchemy\ext\asyncio\session.py", line 1014, in commit
    await greenlet_spawn(self.sync_session.commit)
  File "C:\Users\V\Documents\DEV-VINI\github\m00-projeto\venv\Lib\site-packages\sqlalchemy\util\_concurrency_py3k.py", line 203, in greenlet_spawn
    result = context.switch(value)
  File "C:\Users\V\Documents\DEV-VINI\github\m00-projeto\venv\Lib\site-packages\sqlalchemy\orm\session.py", line 2032, in commit
    trans.commit(_to_root=True)
    ~~~~~~~~~~~~^^^^^^^^^^^^^^^
  File "<string>", line 2, in commit
  File "C:\Users\V\Documents\DEV-VINI\github\m00-projeto\venv\Lib\site-packages\sqlalchemy\orm\state_changes.py", line 139, in _go
    ret_value = fn(self, *arg, **kw)
  File "C:\Users\V\Documents\DEV-VINI\github\m00-projeto\venv\Lib\site-packages\sqlalchemy\orm\session.py", line 1313, in commit
    self._prepare_impl()
    ~~~~~~~~~~~~~~~~~~^^
  File "<string>", line 2, in _prepare_impl
  File "C:\Users\V\Documents\DEV-VINI\github\m00-projeto\venv\Lib\site-packages\sqlalchemy\orm\state_changes.py", line 139, in _go
    ret_value = fn(self, *arg, **kw)
  File "C:\Users\V\Documents\DEV-VINI\github\m00-projeto\venv\Lib\site-packages\sqlalchemy\orm\session.py", line 1288, in _prepare_impl
    self.session.flush()
    ~~~~~~~~~~~~~~~~~~^^
  File "C:\Users\V\Documents\DEV-VINI\github\m00-projeto\venv\Lib\site-packages\sqlalchemy\orm\session.py", line 4345, in flush
    self._flush(objects)
    ~~~~~~~~~~~^^^^^^^^^
  File "C:\Users\V\Documents\DEV-VINI\github\m00-projeto\venv\Lib\site-packages\sqlalchemy\orm\session.py", line 4480, in _flush
    with util.safe_reraise():
         ~~~~~~~~~~~~~~~~~^^
  File "C:\Users\V\Documents\DEV-VINI\github\m00-projeto\venv\Lib\site-packages\sqlalchemy\util\langhelpers.py", line 224, in __exit__
    raise exc_value.with_traceback(exc_tb)
  File "C:\Users\V\Documents\DEV-VINI\github\m00-projeto\venv\Lib\site-packages\sqlalchemy\orm\session.py", line 4441, in _flush
    flush_context.execute()
    ~~~~~~~~~~~~~~~~~~~~~^^
  File "C:\Users\V\Documents\DEV-VINI\github\m00-projeto\venv\Lib\site-packages\sqlalchemy\orm\unitofwork.py", line 466, in execute
    rec.execute(self)
    ~~~~~~~~~~~^^^^^^
  File "C:\Users\V\Documents\DEV-VINI\github\m00-projeto\venv\Lib\site-packages\sqlalchemy\orm\unitofwork.py", line 642, in execute
    util.preloaded.orm_persistence.save_obj(
    ~~~~~~~~~~~~~~~~~~~~~~~~~~~~~~~~~~~~~~~^
        self.mapper,
        ^^^^^^^^^^^^
        uow.states_for_mapper_hierarchy(self.mapper, False, False),
        ^^^^^^^^^^^^^^^^^^^^^^^^^^^^^^^^^^^^^^^^^^^^^^^^^^^^^^^^^^^
        uow,
        ^^^^
    )
    ^
  File "C:\Users\V\Documents\DEV-VINI\github\m00-projeto\venv\Lib\site-packages\sqlalchemy\orm\persistence.py", line 93, in save_obj
    _emit_insert_statements(
    ~~~~~~~~~~~~~~~~~~~~~~~^
        base_mapper,
        ^^^^^^^^^^^^
    ...<3 lines>...
        insert,
        ^^^^^^^
    )
    ^
  File "C:\Users\V\Documents\DEV-VINI\github\m00-projeto\venv\Lib\site-packages\sqlalchemy\orm\persistence.py", line 1233, in _emit_insert_statements
    result = connection.execute(
        statement,
        params,
        execution_options=execution_options,
    )
  File "C:\Users\V\Documents\DEV-VINI\github\m00-projeto\venv\Lib\site-packages\sqlalchemy\engine\base.py", line 1415, in execute
    return meth(
        self,
        distilled_parameters,
        execution_options or NO_OPTIONS,
    )
  File "C:\Users\V\Documents\DEV-VINI\github\m00-projeto\venv\Lib\site-packages\sqlalchemy\sql\elements.py", line 523, in _execute_on_connection
    return connection._execute_clauseelement(
           ~~~~~~~~~~~~~~~~~~~~~~~~~~~~~~~~~^
        self, distilled_params, execution_options
        ^^^^^^^^^^^^^^^^^^^^^^^^^^^^^^^^^^^^^^^^^
    )
    ^
  File "C:\Users\V\Documents\DEV-VINI\github\m00-projeto\venv\Lib\site-packages\sqlalchemy\engine\base.py", line 1637, in _execute_clauseelement
    ret = self._execute_context(
        dialect,
    ...<8 lines>...
        cache_hit=cache_hit,
    )
  File "C:\Users\V\Documents\DEV-VINI\github\m00-projeto\venv\Lib\site-packages\sqlalchemy\engine\base.py", line 1842, in _execute_context
    return self._exec_single_context(
           ~~~~~~~~~~~~~~~~~~~~~~~~~^
        dialect, context, statement, parameters
        ^^^^^^^^^^^^^^^^^^^^^^^^^^^^^^^^^^^^^^^
    )
    ^
  File "C:\Users\V\Documents\DEV-VINI\github\m00-projeto\venv\Lib\site-packages\sqlalchemy\engine\base.py", line 1982, in _exec_single_context
    self._handle_dbapi_exception(
    ~~~~~~~~~~~~~~~~~~~~~~~~~~~~^
        e, str_statement, effective_parameters, cursor, context
        ^^^^^^^^^^^^^^^^^^^^^^^^^^^^^^^^^^^^^^^^^^^^^^^^^^^^^^^
    )
    ^
  File "C:\Users\V\Documents\DEV-VINI\github\m00-projeto\venv\Lib\site-packages\sqlalchemy\engine\base.py", line 2351, in _handle_dbapi_exception
    raise sqlalchemy_exception.with_traceback(exc_info[2]) from e
  File "C:\Users\V\Documents\DEV-VINI\github\m00-projeto\venv\Lib\site-packages\sqlalchemy\engine\base.py", line 1963, in _exec_single_context
    self.dialect.do_execute(
    ~~~~~~~~~~~~~~~~~~~~~~~^
        cursor, str_statement, effective_parameters, context
        ^^^^^^^^^^^^^^^^^^^^^^^^^^^^^^^^^^^^^^^^^^^^^^^^^^^^
    )
    ^
  File "C:\Users\V\Documents\DEV-VINI\github\m00-projeto\venv\Lib\site-packages\sqlalchemy\engine\default.py", line 943, in do_execute
    cursor.execute(statement, parameters)
    ~~~~~~~~~~~~~~^^^^^^^^^^^^^^^^^^^^^^^
  File "C:\Users\V\Documents\DEV-VINI\github\m00-projeto\venv\Lib\site-packages\sqlalchemy\dialects\sqlite\aiosqlite.py", line 149, in execute
    self._adapt_connection._handle_exception(error)
    ~~~~~~~~~~~~~~~~~~~~~~~~~~~~~~~~~~~~~~~~^^^^^^^
  File "C:\Users\V\Documents\DEV-VINI\github\m00-projeto\venv\Lib\site-packages\sqlalchemy\dialects\sqlite\aiosqlite.py", line 300, in _handle_exception
    raise error
  File "C:\Users\V\Documents\DEV-VINI\github\m00-projeto\venv\Lib\site-packages\sqlalchemy\dialects\sqlite\aiosqlite.py", line 131, in execute
    self.await_(_cursor.execute(operation, parameters))
    ~~~~~~~~~~~^^^^^^^^^^^^^^^^^^^^^^^^^^^^^^^^^^^^^^^^
  File "C:\Users\V\Documents\DEV-VINI\github\m00-projeto\venv\Lib\site-packages\sqlalchemy\util\_concurrency_py3k.py", line 132, in await_only
    return current.parent.switch(awaitable)  # type: ignore[no-any-return,attr-defined] # noqa: E501
           ~~~~~~~~~~~~~~~~~~~~~^^^^^^^^^^^
  File "C:\Users\V\Documents\DEV-VINI\github\m00-projeto\venv\Lib\site-packages\sqlalchemy\util\_concurrency_py3k.py", line 196, in greenlet_spawn
    value = await result
            ^^^^^^^^^^^^
  File "C:\Users\V\Documents\DEV-VINI\github\m00-projeto\venv\Lib\site-packages\aiosqlite\cursor.py", line 40, in execute
    await self._execute(self._cursor.execute, sql, parameters)
  File "C:\Users\V\Documents\DEV-VINI\github\m00-projeto\venv\Lib\site-packages\aiosqlite\cursor.py", line 32, in _execute
    return await self._conn._execute(fn, *args, **kwargs)
           ^^^^^^^^^^^^^^^^^^^^^^^^^^^^^^^^^^^^^^^^^^^^^^
  File "C:\Users\V\Documents\DEV-VINI\github\m00-projeto\venv\Lib\site-packages\aiosqlite\core.py", line 122, in _execute
    return await future
           ^^^^^^^^^^^^
  File "C:\Users\V\Documents\DEV-VINI\github\m00-projeto\venv\Lib\site-packages\aiosqlite\core.py", line 105, in run
    result = function()
sqlalchemy.exc.OperationalError: (sqlite3.OperationalError) no such table: tasks
[SQL: INSERT INTO tasks (title, description, completed) VALUES (?, ?, ?)]
[parameters: ('Nova Tarefa', 'Descrição de teste', 0)]
(Background on this error at: https://sqlalche.me/e/20/e3q8)
2025-06-01 16:31:42,352 | ERROR | m00-backend | Erro inesperado em http://testserver/tasks/: (sqlite3.OperationalError) no such table: tasks
[SQL: SELECT tasks.id, tasks.title, tasks.description, tasks.completed 
FROM tasks]
(Background on this error at: https://sqlalche.me/e/20/e3q8)
Traceback (most recent call last):
  File "C:\Users\V\Documents\DEV-VINI\github\m00-projeto\venv\Lib\site-packages\sqlalchemy\engine\base.py", line 1963, in _exec_single_context
    self.dialect.do_execute(
    ~~~~~~~~~~~~~~~~~~~~~~~^
        cursor, str_statement, effective_parameters, context
        ^^^^^^^^^^^^^^^^^^^^^^^^^^^^^^^^^^^^^^^^^^^^^^^^^^^^
    )
    ^
  File "C:\Users\V\Documents\DEV-VINI\github\m00-projeto\venv\Lib\site-packages\sqlalchemy\engine\default.py", line 943, in do_execute
    cursor.execute(statement, parameters)
    ~~~~~~~~~~~~~~^^^^^^^^^^^^^^^^^^^^^^^
  File "C:\Users\V\Documents\DEV-VINI\github\m00-projeto\venv\Lib\site-packages\sqlalchemy\dialects\sqlite\aiosqlite.py", line 149, in execute
    self._adapt_connection._handle_exception(error)
    ~~~~~~~~~~~~~~~~~~~~~~~~~~~~~~~~~~~~~~~~^^^^^^^
  File "C:\Users\V\Documents\DEV-VINI\github\m00-projeto\venv\Lib\site-packages\sqlalchemy\dialects\sqlite\aiosqlite.py", line 300, in _handle_exception
    raise error
  File "C:\Users\V\Documents\DEV-VINI\github\m00-projeto\venv\Lib\site-packages\sqlalchemy\dialects\sqlite\aiosqlite.py", line 131, in execute
    self.await_(_cursor.execute(operation, parameters))
    ~~~~~~~~~~~^^^^^^^^^^^^^^^^^^^^^^^^^^^^^^^^^^^^^^^^
  File "C:\Users\V\Documents\DEV-VINI\github\m00-projeto\venv\Lib\site-packages\sqlalchemy\util\_concurrency_py3k.py", line 132, in await_only
    return current.parent.switch(awaitable)  # type: ignore[no-any-return,attr-defined] # noqa: E501
           ~~~~~~~~~~~~~~~~~~~~~^^^^^^^^^^^
  File "C:\Users\V\Documents\DEV-VINI\github\m00-projeto\venv\Lib\site-packages\sqlalchemy\util\_concurrency_py3k.py", line 196, in greenlet_spawn
    value = await result
            ^^^^^^^^^^^^
  File "C:\Users\V\Documents\DEV-VINI\github\m00-projeto\venv\Lib\site-packages\aiosqlite\cursor.py", line 40, in execute
    await self._execute(self._cursor.execute, sql, parameters)
  File "C:\Users\V\Documents\DEV-VINI\github\m00-projeto\venv\Lib\site-packages\aiosqlite\cursor.py", line 32, in _execute
    return await self._conn._execute(fn, *args, **kwargs)
           ^^^^^^^^^^^^^^^^^^^^^^^^^^^^^^^^^^^^^^^^^^^^^^
  File "C:\Users\V\Documents\DEV-VINI\github\m00-projeto\venv\Lib\site-packages\aiosqlite\core.py", line 122, in _execute
    return await future
           ^^^^^^^^^^^^
  File "C:\Users\V\Documents\DEV-VINI\github\m00-projeto\venv\Lib\site-packages\aiosqlite\core.py", line 105, in run
    result = function()
sqlite3.OperationalError: no such table: tasks

The above exception was the direct cause of the following exception:

Traceback (most recent call last):
  File "C:\Users\V\Documents\DEV-VINI\github\m00-projeto\venv\Lib\site-packages\starlette\middleware\errors.py", line 165, in __call__
    await self.app(scope, receive, _send)
  File "C:\Users\V\Documents\DEV-VINI\github\m00-projeto\venv\Lib\site-packages\starlette\middleware\exceptions.py", line 62, in __call__
    await wrap_app_handling_exceptions(self.app, conn)(scope, receive, send)
  File "C:\Users\V\Documents\DEV-VINI\github\m00-projeto\venv\Lib\site-packages\starlette\_exception_handler.py", line 53, in wrapped_app
    raise exc
  File "C:\Users\V\Documents\DEV-VINI\github\m00-projeto\venv\Lib\site-packages\starlette\_exception_handler.py", line 42, in wrapped_app
    await app(scope, receive, sender)
  File "C:\Users\V\Documents\DEV-VINI\github\m00-projeto\venv\Lib\site-packages\starlette\routing.py", line 714, in __call__
    await self.middleware_stack(scope, receive, send)
  File "C:\Users\V\Documents\DEV-VINI\github\m00-projeto\venv\Lib\site-packages\starlette\routing.py", line 734, in app
    await route.handle(scope, receive, send)
  File "C:\Users\V\Documents\DEV-VINI\github\m00-projeto\venv\Lib\site-packages\starlette\routing.py", line 288, in handle
    await self.app(scope, receive, send)
  File "C:\Users\V\Documents\DEV-VINI\github\m00-projeto\venv\Lib\site-packages\starlette\routing.py", line 76, in app
    await wrap_app_handling_exceptions(app, request)(scope, receive, send)
  File "C:\Users\V\Documents\DEV-VINI\github\m00-projeto\venv\Lib\site-packages\starlette\_exception_handler.py", line 53, in wrapped_app
    raise exc
  File "C:\Users\V\Documents\DEV-VINI\github\m00-projeto\venv\Lib\site-packages\starlette\_exception_handler.py", line 42, in wrapped_app
    await app(scope, receive, sender)
  File "C:\Users\V\Documents\DEV-VINI\github\m00-projeto\venv\Lib\site-packages\starlette\routing.py", line 73, in app
    response = await f(request)
               ^^^^^^^^^^^^^^^^
  File "C:\Users\V\Documents\DEV-VINI\github\m00-projeto\venv\Lib\site-packages\fastapi\routing.py", line 301, in app
    raw_response = await run_endpoint_function(
                   ^^^^^^^^^^^^^^^^^^^^^^^^^^^^
    ...<3 lines>...
    )
    ^
  File "C:\Users\V\Documents\DEV-VINI\github\m00-projeto\venv\Lib\site-packages\fastapi\routing.py", line 212, in run_endpoint_function
    return await dependant.call(**values)
           ^^^^^^^^^^^^^^^^^^^^^^^^^^^^^^
  File "C:\Users\V\Documents\DEV-VINI\github\m00-projeto\backend\app\api\tasks.py", line 38, in get_tasks
    result = await db.execute(select(TaskModel))
             ^^^^^^^^^^^^^^^^^^^^^^^^^^^^^^^^^^^
  File "C:\Users\V\Documents\DEV-VINI\github\m00-projeto\venv\Lib\site-packages\sqlalchemy\ext\asyncio\session.py", line 463, in execute
    result = await greenlet_spawn(
             ^^^^^^^^^^^^^^^^^^^^^
    ...<6 lines>...
    )
    ^
  File "C:\Users\V\Documents\DEV-VINI\github\m00-projeto\venv\Lib\site-packages\sqlalchemy\util\_concurrency_py3k.py", line 201, in greenlet_spawn
    result = context.throw(*sys.exc_info())
  File "C:\Users\V\Documents\DEV-VINI\github\m00-projeto\venv\Lib\site-packages\sqlalchemy\orm\session.py", line 2365, in execute
    return self._execute_internal(
           ~~~~~~~~~~~~~~~~~~~~~~^
        statement,
        ^^^^^^^^^^
    ...<4 lines>...
        _add_event=_add_event,
        ^^^^^^^^^^^^^^^^^^^^^^
    )
    ^
  File "C:\Users\V\Documents\DEV-VINI\github\m00-projeto\venv\Lib\site-packages\sqlalchemy\orm\session.py", line 2251, in _execute_internal
    result: Result[Any] = compile_state_cls.orm_execute_statement(
                          ~~~~~~~~~~~~~~~~~~~~~~~~~~~~~~~~~~~~~~~^
        self,
        ^^^^^
    ...<4 lines>...
        conn,
        ^^^^^
    )
    ^
  File "C:\Users\V\Documents\DEV-VINI\github\m00-projeto\venv\Lib\site-packages\sqlalchemy\orm\context.py", line 306, in orm_execute_statement
    result = conn.execute(
        statement, params or {}, execution_options=execution_options
    )
  File "C:\Users\V\Documents\DEV-VINI\github\m00-projeto\venv\Lib\site-packages\sqlalchemy\engine\base.py", line 1415, in execute
    return meth(
        self,
        distilled_parameters,
        execution_options or NO_OPTIONS,
    )
  File "C:\Users\V\Documents\DEV-VINI\github\m00-projeto\venv\Lib\site-packages\sqlalchemy\sql\elements.py", line 523, in _execute_on_connection
    return connection._execute_clauseelement(
           ~~~~~~~~~~~~~~~~~~~~~~~~~~~~~~~~~^
        self, distilled_params, execution_options
        ^^^^^^^^^^^^^^^^^^^^^^^^^^^^^^^^^^^^^^^^^
    )
    ^
  File "C:\Users\V\Documents\DEV-VINI\github\m00-projeto\venv\Lib\site-packages\sqlalchemy\engine\base.py", line 1637, in _execute_clauseelement
    ret = self._execute_context(
        dialect,
    ...<8 lines>...
        cache_hit=cache_hit,
    )
  File "C:\Users\V\Documents\DEV-VINI\github\m00-projeto\venv\Lib\site-packages\sqlalchemy\engine\base.py", line 1842, in _execute_context
    return self._exec_single_context(
           ~~~~~~~~~~~~~~~~~~~~~~~~~^
        dialect, context, statement, parameters
        ^^^^^^^^^^^^^^^^^^^^^^^^^^^^^^^^^^^^^^^
    )
    ^
  File "C:\Users\V\Documents\DEV-VINI\github\m00-projeto\venv\Lib\site-packages\sqlalchemy\engine\base.py", line 1982, in _exec_single_context
    self._handle_dbapi_exception(
    ~~~~~~~~~~~~~~~~~~~~~~~~~~~~^
        e, str_statement, effective_parameters, cursor, context
        ^^^^^^^^^^^^^^^^^^^^^^^^^^^^^^^^^^^^^^^^^^^^^^^^^^^^^^^
    )
    ^
  File "C:\Users\V\Documents\DEV-VINI\github\m00-projeto\venv\Lib\site-packages\sqlalchemy\engine\base.py", line 2351, in _handle_dbapi_exception
    raise sqlalchemy_exception.with_traceback(exc_info[2]) from e
  File "C:\Users\V\Documents\DEV-VINI\github\m00-projeto\venv\Lib\site-packages\sqlalchemy\engine\base.py", line 1963, in _exec_single_context
    self.dialect.do_execute(
    ~~~~~~~~~~~~~~~~~~~~~~~^
        cursor, str_statement, effective_parameters, context
        ^^^^^^^^^^^^^^^^^^^^^^^^^^^^^^^^^^^^^^^^^^^^^^^^^^^^
    )
    ^
  File "C:\Users\V\Documents\DEV-VINI\github\m00-projeto\venv\Lib\site-packages\sqlalchemy\engine\default.py", line 943, in do_execute
    cursor.execute(statement, parameters)
    ~~~~~~~~~~~~~~^^^^^^^^^^^^^^^^^^^^^^^
  File "C:\Users\V\Documents\DEV-VINI\github\m00-projeto\venv\Lib\site-packages\sqlalchemy\dialects\sqlite\aiosqlite.py", line 149, in execute
    self._adapt_connection._handle_exception(error)
    ~~~~~~~~~~~~~~~~~~~~~~~~~~~~~~~~~~~~~~~~^^^^^^^
  File "C:\Users\V\Documents\DEV-VINI\github\m00-projeto\venv\Lib\site-packages\sqlalchemy\dialects\sqlite\aiosqlite.py", line 300, in _handle_exception
    raise error
  File "C:\Users\V\Documents\DEV-VINI\github\m00-projeto\venv\Lib\site-packages\sqlalchemy\dialects\sqlite\aiosqlite.py", line 131, in execute
    self.await_(_cursor.execute(operation, parameters))
    ~~~~~~~~~~~^^^^^^^^^^^^^^^^^^^^^^^^^^^^^^^^^^^^^^^^
  File "C:\Users\V\Documents\DEV-VINI\github\m00-projeto\venv\Lib\site-packages\sqlalchemy\util\_concurrency_py3k.py", line 132, in await_only
    return current.parent.switch(awaitable)  # type: ignore[no-any-return,attr-defined] # noqa: E501
           ~~~~~~~~~~~~~~~~~~~~~^^^^^^^^^^^
  File "C:\Users\V\Documents\DEV-VINI\github\m00-projeto\venv\Lib\site-packages\sqlalchemy\util\_concurrency_py3k.py", line 196, in greenlet_spawn
    value = await result
            ^^^^^^^^^^^^
  File "C:\Users\V\Documents\DEV-VINI\github\m00-projeto\venv\Lib\site-packages\aiosqlite\cursor.py", line 40, in execute
    await self._execute(self._cursor.execute, sql, parameters)
  File "C:\Users\V\Documents\DEV-VINI\github\m00-projeto\venv\Lib\site-packages\aiosqlite\cursor.py", line 32, in _execute
    return await self._conn._execute(fn, *args, **kwargs)
           ^^^^^^^^^^^^^^^^^^^^^^^^^^^^^^^^^^^^^^^^^^^^^^
  File "C:\Users\V\Documents\DEV-VINI\github\m00-projeto\venv\Lib\site-packages\aiosqlite\core.py", line 122, in _execute
    return await future
           ^^^^^^^^^^^^
  File "C:\Users\V\Documents\DEV-VINI\github\m00-projeto\venv\Lib\site-packages\aiosqlite\core.py", line 105, in run
    result = function()
sqlalchemy.exc.OperationalError: (sqlite3.OperationalError) no such table: tasks
[SQL: SELECT tasks.id, tasks.title, tasks.description, tasks.completed 
FROM tasks]
(Background on this error at: https://sqlalche.me/e/20/e3q8)
2025-06-01 16:31:42,788 | ERROR | m00-backend | Erro inesperado em http://testserver/tasks/: (sqlite3.OperationalError) no such table: tasks
[SQL: INSERT INTO tasks (title, description, completed) VALUES (?, ?, ?)]
[parameters: ('Tarefa para GET', 'Desc GET', 0)]
(Background on this error at: https://sqlalche.me/e/20/e3q8)
Traceback (most recent call last):
  File "C:\Users\V\Documents\DEV-VINI\github\m00-projeto\venv\Lib\site-packages\sqlalchemy\engine\base.py", line 1963, in _exec_single_context
    self.dialect.do_execute(
    ~~~~~~~~~~~~~~~~~~~~~~~^
        cursor, str_statement, effective_parameters, context
        ^^^^^^^^^^^^^^^^^^^^^^^^^^^^^^^^^^^^^^^^^^^^^^^^^^^^
    )
    ^
  File "C:\Users\V\Documents\DEV-VINI\github\m00-projeto\venv\Lib\site-packages\sqlalchemy\engine\default.py", line 943, in do_execute
    cursor.execute(statement, parameters)
    ~~~~~~~~~~~~~~^^^^^^^^^^^^^^^^^^^^^^^
  File "C:\Users\V\Documents\DEV-VINI\github\m00-projeto\venv\Lib\site-packages\sqlalchemy\dialects\sqlite\aiosqlite.py", line 149, in execute
    self._adapt_connection._handle_exception(error)
    ~~~~~~~~~~~~~~~~~~~~~~~~~~~~~~~~~~~~~~~~^^^^^^^
  File "C:\Users\V\Documents\DEV-VINI\github\m00-projeto\venv\Lib\site-packages\sqlalchemy\dialects\sqlite\aiosqlite.py", line 300, in _handle_exception
    raise error
  File "C:\Users\V\Documents\DEV-VINI\github\m00-projeto\venv\Lib\site-packages\sqlalchemy\dialects\sqlite\aiosqlite.py", line 131, in execute
    self.await_(_cursor.execute(operation, parameters))
    ~~~~~~~~~~~^^^^^^^^^^^^^^^^^^^^^^^^^^^^^^^^^^^^^^^^
  File "C:\Users\V\Documents\DEV-VINI\github\m00-projeto\venv\Lib\site-packages\sqlalchemy\util\_concurrency_py3k.py", line 132, in await_only
    return current.parent.switch(awaitable)  # type: ignore[no-any-return,attr-defined] # noqa: E501
           ~~~~~~~~~~~~~~~~~~~~~^^^^^^^^^^^
  File "C:\Users\V\Documents\DEV-VINI\github\m00-projeto\venv\Lib\site-packages\sqlalchemy\util\_concurrency_py3k.py", line 196, in greenlet_spawn
    value = await result
            ^^^^^^^^^^^^
  File "C:\Users\V\Documents\DEV-VINI\github\m00-projeto\venv\Lib\site-packages\aiosqlite\cursor.py", line 40, in execute
    await self._execute(self._cursor.execute, sql, parameters)
  File "C:\Users\V\Documents\DEV-VINI\github\m00-projeto\venv\Lib\site-packages\aiosqlite\cursor.py", line 32, in _execute
    return await self._conn._execute(fn, *args, **kwargs)
           ^^^^^^^^^^^^^^^^^^^^^^^^^^^^^^^^^^^^^^^^^^^^^^
  File "C:\Users\V\Documents\DEV-VINI\github\m00-projeto\venv\Lib\site-packages\aiosqlite\core.py", line 122, in _execute
    return await future
           ^^^^^^^^^^^^
  File "C:\Users\V\Documents\DEV-VINI\github\m00-projeto\venv\Lib\site-packages\aiosqlite\core.py", line 105, in run
    result = function()
sqlite3.OperationalError: no such table: tasks

The above exception was the direct cause of the following exception:

Traceback (most recent call last):
  File "C:\Users\V\Documents\DEV-VINI\github\m00-projeto\venv\Lib\site-packages\starlette\middleware\errors.py", line 165, in __call__
    await self.app(scope, receive, _send)
  File "C:\Users\V\Documents\DEV-VINI\github\m00-projeto\venv\Lib\site-packages\starlette\middleware\exceptions.py", line 62, in __call__
    await wrap_app_handling_exceptions(self.app, conn)(scope, receive, send)
  File "C:\Users\V\Documents\DEV-VINI\github\m00-projeto\venv\Lib\site-packages\starlette\_exception_handler.py", line 53, in wrapped_app
    raise exc
  File "C:\Users\V\Documents\DEV-VINI\github\m00-projeto\venv\Lib\site-packages\starlette\_exception_handler.py", line 42, in wrapped_app
    await app(scope, receive, sender)
  File "C:\Users\V\Documents\DEV-VINI\github\m00-projeto\venv\Lib\site-packages\starlette\routing.py", line 714, in __call__
    await self.middleware_stack(scope, receive, send)
  File "C:\Users\V\Documents\DEV-VINI\github\m00-projeto\venv\Lib\site-packages\starlette\routing.py", line 734, in app
    await route.handle(scope, receive, send)
  File "C:\Users\V\Documents\DEV-VINI\github\m00-projeto\venv\Lib\site-packages\starlette\routing.py", line 288, in handle
    await self.app(scope, receive, send)
  File "C:\Users\V\Documents\DEV-VINI\github\m00-projeto\venv\Lib\site-packages\starlette\routing.py", line 76, in app
    await wrap_app_handling_exceptions(app, request)(scope, receive, send)
  File "C:\Users\V\Documents\DEV-VINI\github\m00-projeto\venv\Lib\site-packages\starlette\_exception_handler.py", line 53, in wrapped_app
    raise exc
  File "C:\Users\V\Documents\DEV-VINI\github\m00-projeto\venv\Lib\site-packages\starlette\_exception_handler.py", line 42, in wrapped_app
    await app(scope, receive, sender)
  File "C:\Users\V\Documents\DEV-VINI\github\m00-projeto\venv\Lib\site-packages\starlette\routing.py", line 73, in app
    response = await f(request)
               ^^^^^^^^^^^^^^^^
  File "C:\Users\V\Documents\DEV-VINI\github\m00-projeto\venv\Lib\site-packages\fastapi\routing.py", line 301, in app
    raw_response = await run_endpoint_function(
                   ^^^^^^^^^^^^^^^^^^^^^^^^^^^^
    ...<3 lines>...
    )
    ^
  File "C:\Users\V\Documents\DEV-VINI\github\m00-projeto\venv\Lib\site-packages\fastapi\routing.py", line 212, in run_endpoint_function
    return await dependant.call(**values)
           ^^^^^^^^^^^^^^^^^^^^^^^^^^^^^^
  File "C:\Users\V\Documents\DEV-VINI\github\m00-projeto\backend\app\api\tasks.py", line 29, in create_new_task
    task_created = await create_task(db, task)
                   ^^^^^^^^^^^^^^^^^^^^^^^^^^^
  File "C:\Users\V\Documents\DEV-VINI\github\m00-projeto\backend\app\services\task_service.py", line 23, in create_task
    await db.commit()
  File "C:\Users\V\Documents\DEV-VINI\github\m00-projeto\venv\Lib\site-packages\sqlalchemy\ext\asyncio\session.py", line 1014, in commit
    await greenlet_spawn(self.sync_session.commit)
  File "C:\Users\V\Documents\DEV-VINI\github\m00-projeto\venv\Lib\site-packages\sqlalchemy\util\_concurrency_py3k.py", line 203, in greenlet_spawn
    result = context.switch(value)
  File "C:\Users\V\Documents\DEV-VINI\github\m00-projeto\venv\Lib\site-packages\sqlalchemy\orm\session.py", line 2032, in commit
    trans.commit(_to_root=True)
    ~~~~~~~~~~~~^^^^^^^^^^^^^^^
  File "<string>", line 2, in commit
  File "C:\Users\V\Documents\DEV-VINI\github\m00-projeto\venv\Lib\site-packages\sqlalchemy\orm\state_changes.py", line 139, in _go
    ret_value = fn(self, *arg, **kw)
  File "C:\Users\V\Documents\DEV-VINI\github\m00-projeto\venv\Lib\site-packages\sqlalchemy\orm\session.py", line 1313, in commit
    self._prepare_impl()
    ~~~~~~~~~~~~~~~~~~^^
  File "<string>", line 2, in _prepare_impl
  File "C:\Users\V\Documents\DEV-VINI\github\m00-projeto\venv\Lib\site-packages\sqlalchemy\orm\state_changes.py", line 139, in _go
    ret_value = fn(self, *arg, **kw)
  File "C:\Users\V\Documents\DEV-VINI\github\m00-projeto\venv\Lib\site-packages\sqlalchemy\orm\session.py", line 1288, in _prepare_impl
    self.session.flush()
    ~~~~~~~~~~~~~~~~~~^^
  File "C:\Users\V\Documents\DEV-VINI\github\m00-projeto\venv\Lib\site-packages\sqlalchemy\orm\session.py", line 4345, in flush
    self._flush(objects)
    ~~~~~~~~~~~^^^^^^^^^
  File "C:\Users\V\Documents\DEV-VINI\github\m00-projeto\venv\Lib\site-packages\sqlalchemy\orm\session.py", line 4480, in _flush
    with util.safe_reraise():
         ~~~~~~~~~~~~~~~~~^^
  File "C:\Users\V\Documents\DEV-VINI\github\m00-projeto\venv\Lib\site-packages\sqlalchemy\util\langhelpers.py", line 224, in __exit__
    raise exc_value.with_traceback(exc_tb)
  File "C:\Users\V\Documents\DEV-VINI\github\m00-projeto\venv\Lib\site-packages\sqlalchemy\orm\session.py", line 4441, in _flush
    flush_context.execute()
    ~~~~~~~~~~~~~~~~~~~~~^^
  File "C:\Users\V\Documents\DEV-VINI\github\m00-projeto\venv\Lib\site-packages\sqlalchemy\orm\unitofwork.py", line 466, in execute
    rec.execute(self)
    ~~~~~~~~~~~^^^^^^
  File "C:\Users\V\Documents\DEV-VINI\github\m00-projeto\venv\Lib\site-packages\sqlalchemy\orm\unitofwork.py", line 642, in execute
    util.preloaded.orm_persistence.save_obj(
    ~~~~~~~~~~~~~~~~~~~~~~~~~~~~~~~~~~~~~~~^
        self.mapper,
        ^^^^^^^^^^^^
        uow.states_for_mapper_hierarchy(self.mapper, False, False),
        ^^^^^^^^^^^^^^^^^^^^^^^^^^^^^^^^^^^^^^^^^^^^^^^^^^^^^^^^^^^
        uow,
        ^^^^
    )
    ^
  File "C:\Users\V\Documents\DEV-VINI\github\m00-projeto\venv\Lib\site-packages\sqlalchemy\orm\persistence.py", line 93, in save_obj
    _emit_insert_statements(
    ~~~~~~~~~~~~~~~~~~~~~~~^
        base_mapper,
        ^^^^^^^^^^^^
    ...<3 lines>...
        insert,
        ^^^^^^^
    )
    ^
  File "C:\Users\V\Documents\DEV-VINI\github\m00-projeto\venv\Lib\site-packages\sqlalchemy\orm\persistence.py", line 1233, in _emit_insert_statements
    result = connection.execute(
        statement,
        params,
        execution_options=execution_options,
    )
  File "C:\Users\V\Documents\DEV-VINI\github\m00-projeto\venv\Lib\site-packages\sqlalchemy\engine\base.py", line 1415, in execute
    return meth(
        self,
        distilled_parameters,
        execution_options or NO_OPTIONS,
    )
  File "C:\Users\V\Documents\DEV-VINI\github\m00-projeto\venv\Lib\site-packages\sqlalchemy\sql\elements.py", line 523, in _execute_on_connection
    return connection._execute_clauseelement(
           ~~~~~~~~~~~~~~~~~~~~~~~~~~~~~~~~~^
        self, distilled_params, execution_options
        ^^^^^^^^^^^^^^^^^^^^^^^^^^^^^^^^^^^^^^^^^
    )
    ^
  File "C:\Users\V\Documents\DEV-VINI\github\m00-projeto\venv\Lib\site-packages\sqlalchemy\engine\base.py", line 1637, in _execute_clauseelement
    ret = self._execute_context(
        dialect,
    ...<8 lines>...
        cache_hit=cache_hit,
    )
  File "C:\Users\V\Documents\DEV-VINI\github\m00-projeto\venv\Lib\site-packages\sqlalchemy\engine\base.py", line 1842, in _execute_context
    return self._exec_single_context(
           ~~~~~~~~~~~~~~~~~~~~~~~~~^
        dialect, context, statement, parameters
        ^^^^^^^^^^^^^^^^^^^^^^^^^^^^^^^^^^^^^^^
    )
    ^
  File "C:\Users\V\Documents\DEV-VINI\github\m00-projeto\venv\Lib\site-packages\sqlalchemy\engine\base.py", line 1982, in _exec_single_context
    self._handle_dbapi_exception(
    ~~~~~~~~~~~~~~~~~~~~~~~~~~~~^
        e, str_statement, effective_parameters, cursor, context
        ^^^^^^^^^^^^^^^^^^^^^^^^^^^^^^^^^^^^^^^^^^^^^^^^^^^^^^^
    )
    ^
  File "C:\Users\V\Documents\DEV-VINI\github\m00-projeto\venv\Lib\site-packages\sqlalchemy\engine\base.py", line 2351, in _handle_dbapi_exception
    raise sqlalchemy_exception.with_traceback(exc_info[2]) from e
  File "C:\Users\V\Documents\DEV-VINI\github\m00-projeto\venv\Lib\site-packages\sqlalchemy\engine\base.py", line 1963, in _exec_single_context
    self.dialect.do_execute(
    ~~~~~~~~~~~~~~~~~~~~~~~^
        cursor, str_statement, effective_parameters, context
        ^^^^^^^^^^^^^^^^^^^^^^^^^^^^^^^^^^^^^^^^^^^^^^^^^^^^
    )
    ^
  File "C:\Users\V\Documents\DEV-VINI\github\m00-projeto\venv\Lib\site-packages\sqlalchemy\engine\default.py", line 943, in do_execute
    cursor.execute(statement, parameters)
    ~~~~~~~~~~~~~~^^^^^^^^^^^^^^^^^^^^^^^
  File "C:\Users\V\Documents\DEV-VINI\github\m00-projeto\venv\Lib\site-packages\sqlalchemy\dialects\sqlite\aiosqlite.py", line 149, in execute
    self._adapt_connection._handle_exception(error)
    ~~~~~~~~~~~~~~~~~~~~~~~~~~~~~~~~~~~~~~~~^^^^^^^
  File "C:\Users\V\Documents\DEV-VINI\github\m00-projeto\venv\Lib\site-packages\sqlalchemy\dialects\sqlite\aiosqlite.py", line 300, in _handle_exception
    raise error
  File "C:\Users\V\Documents\DEV-VINI\github\m00-projeto\venv\Lib\site-packages\sqlalchemy\dialects\sqlite\aiosqlite.py", line 131, in execute
    self.await_(_cursor.execute(operation, parameters))
    ~~~~~~~~~~~^^^^^^^^^^^^^^^^^^^^^^^^^^^^^^^^^^^^^^^^
  File "C:\Users\V\Documents\DEV-VINI\github\m00-projeto\venv\Lib\site-packages\sqlalchemy\util\_concurrency_py3k.py", line 132, in await_only
    return current.parent.switch(awaitable)  # type: ignore[no-any-return,attr-defined] # noqa: E501
           ~~~~~~~~~~~~~~~~~~~~~^^^^^^^^^^^
  File "C:\Users\V\Documents\DEV-VINI\github\m00-projeto\venv\Lib\site-packages\sqlalchemy\util\_concurrency_py3k.py", line 196, in greenlet_spawn
    value = await result
            ^^^^^^^^^^^^
  File "C:\Users\V\Documents\DEV-VINI\github\m00-projeto\venv\Lib\site-packages\aiosqlite\cursor.py", line 40, in execute
    await self._execute(self._cursor.execute, sql, parameters)
  File "C:\Users\V\Documents\DEV-VINI\github\m00-projeto\venv\Lib\site-packages\aiosqlite\cursor.py", line 32, in _execute
    return await self._conn._execute(fn, *args, **kwargs)
           ^^^^^^^^^^^^^^^^^^^^^^^^^^^^^^^^^^^^^^^^^^^^^^
  File "C:\Users\V\Documents\DEV-VINI\github\m00-projeto\venv\Lib\site-packages\aiosqlite\core.py", line 122, in _execute
    return await future
           ^^^^^^^^^^^^
  File "C:\Users\V\Documents\DEV-VINI\github\m00-projeto\venv\Lib\site-packages\aiosqlite\core.py", line 105, in run
    result = function()
sqlalchemy.exc.OperationalError: (sqlite3.OperationalError) no such table: tasks
[SQL: INSERT INTO tasks (title, description, completed) VALUES (?, ?, ?)]
[parameters: ('Tarefa para GET', 'Desc GET', 0)]
(Background on this error at: https://sqlalche.me/e/20/e3q8)
2025-06-01 16:31:43,373 | ERROR | m00-backend | Erro inesperado em http://testserver/tasks/: (sqlite3.OperationalError) no such table: tasks
[SQL: INSERT INTO tasks (title, description, completed) VALUES (?, ?, ?)]
[parameters: ('Tarefa PUT', 'Desc PUT', 0)]
(Background on this error at: https://sqlalche.me/e/20/e3q8)
Traceback (most recent call last):
  File "C:\Users\V\Documents\DEV-VINI\github\m00-projeto\venv\Lib\site-packages\sqlalchemy\engine\base.py", line 1963, in _exec_single_context
    self.dialect.do_execute(
    ~~~~~~~~~~~~~~~~~~~~~~~^
        cursor, str_statement, effective_parameters, context
        ^^^^^^^^^^^^^^^^^^^^^^^^^^^^^^^^^^^^^^^^^^^^^^^^^^^^
    )
    ^
  File "C:\Users\V\Documents\DEV-VINI\github\m00-projeto\venv\Lib\site-packages\sqlalchemy\engine\default.py", line 943, in do_execute
    cursor.execute(statement, parameters)
    ~~~~~~~~~~~~~~^^^^^^^^^^^^^^^^^^^^^^^
  File "C:\Users\V\Documents\DEV-VINI\github\m00-projeto\venv\Lib\site-packages\sqlalchemy\dialects\sqlite\aiosqlite.py", line 149, in execute
    self._adapt_connection._handle_exception(error)
    ~~~~~~~~~~~~~~~~~~~~~~~~~~~~~~~~~~~~~~~~^^^^^^^
  File "C:\Users\V\Documents\DEV-VINI\github\m00-projeto\venv\Lib\site-packages\sqlalchemy\dialects\sqlite\aiosqlite.py", line 300, in _handle_exception
    raise error
  File "C:\Users\V\Documents\DEV-VINI\github\m00-projeto\venv\Lib\site-packages\sqlalchemy\dialects\sqlite\aiosqlite.py", line 131, in execute
    self.await_(_cursor.execute(operation, parameters))
    ~~~~~~~~~~~^^^^^^^^^^^^^^^^^^^^^^^^^^^^^^^^^^^^^^^^
  File "C:\Users\V\Documents\DEV-VINI\github\m00-projeto\venv\Lib\site-packages\sqlalchemy\util\_concurrency_py3k.py", line 132, in await_only
    return current.parent.switch(awaitable)  # type: ignore[no-any-return,attr-defined] # noqa: E501
           ~~~~~~~~~~~~~~~~~~~~~^^^^^^^^^^^
  File "C:\Users\V\Documents\DEV-VINI\github\m00-projeto\venv\Lib\site-packages\sqlalchemy\util\_concurrency_py3k.py", line 196, in greenlet_spawn
    value = await result
            ^^^^^^^^^^^^
  File "C:\Users\V\Documents\DEV-VINI\github\m00-projeto\venv\Lib\site-packages\aiosqlite\cursor.py", line 40, in execute
    await self._execute(self._cursor.execute, sql, parameters)
  File "C:\Users\V\Documents\DEV-VINI\github\m00-projeto\venv\Lib\site-packages\aiosqlite\cursor.py", line 32, in _execute
    return await self._conn._execute(fn, *args, **kwargs)
           ^^^^^^^^^^^^^^^^^^^^^^^^^^^^^^^^^^^^^^^^^^^^^^
  File "C:\Users\V\Documents\DEV-VINI\github\m00-projeto\venv\Lib\site-packages\aiosqlite\core.py", line 122, in _execute
    return await future
           ^^^^^^^^^^^^
  File "C:\Users\V\Documents\DEV-VINI\github\m00-projeto\venv\Lib\site-packages\aiosqlite\core.py", line 105, in run
    result = function()
sqlite3.OperationalError: no such table: tasks

The above exception was the direct cause of the following exception:

Traceback (most recent call last):
  File "C:\Users\V\Documents\DEV-VINI\github\m00-projeto\venv\Lib\site-packages\starlette\middleware\errors.py", line 165, in __call__
    await self.app(scope, receive, _send)
  File "C:\Users\V\Documents\DEV-VINI\github\m00-projeto\venv\Lib\site-packages\starlette\middleware\exceptions.py", line 62, in __call__
    await wrap_app_handling_exceptions(self.app, conn)(scope, receive, send)
  File "C:\Users\V\Documents\DEV-VINI\github\m00-projeto\venv\Lib\site-packages\starlette\_exception_handler.py", line 53, in wrapped_app
    raise exc
  File "C:\Users\V\Documents\DEV-VINI\github\m00-projeto\venv\Lib\site-packages\starlette\_exception_handler.py", line 42, in wrapped_app
    await app(scope, receive, sender)
  File "C:\Users\V\Documents\DEV-VINI\github\m00-projeto\venv\Lib\site-packages\starlette\routing.py", line 714, in __call__
    await self.middleware_stack(scope, receive, send)
  File "C:\Users\V\Documents\DEV-VINI\github\m00-projeto\venv\Lib\site-packages\starlette\routing.py", line 734, in app
    await route.handle(scope, receive, send)
  File "C:\Users\V\Documents\DEV-VINI\github\m00-projeto\venv\Lib\site-packages\starlette\routing.py", line 288, in handle
    await self.app(scope, receive, send)
  File "C:\Users\V\Documents\DEV-VINI\github\m00-projeto\venv\Lib\site-packages\starlette\routing.py", line 76, in app
    await wrap_app_handling_exceptions(app, request)(scope, receive, send)
  File "C:\Users\V\Documents\DEV-VINI\github\m00-projeto\venv\Lib\site-packages\starlette\_exception_handler.py", line 53, in wrapped_app
    raise exc
  File "C:\Users\V\Documents\DEV-VINI\github\m00-projeto\venv\Lib\site-packages\starlette\_exception_handler.py", line 42, in wrapped_app
    await app(scope, receive, sender)
  File "C:\Users\V\Documents\DEV-VINI\github\m00-projeto\venv\Lib\site-packages\starlette\routing.py", line 73, in app
    response = await f(request)
               ^^^^^^^^^^^^^^^^
  File "C:\Users\V\Documents\DEV-VINI\github\m00-projeto\venv\Lib\site-packages\fastapi\routing.py", line 301, in app
    raw_response = await run_endpoint_function(
                   ^^^^^^^^^^^^^^^^^^^^^^^^^^^^
    ...<3 lines>...
    )
    ^
  File "C:\Users\V\Documents\DEV-VINI\github\m00-projeto\venv\Lib\site-packages\fastapi\routing.py", line 212, in run_endpoint_function
    return await dependant.call(**values)
           ^^^^^^^^^^^^^^^^^^^^^^^^^^^^^^
  File "C:\Users\V\Documents\DEV-VINI\github\m00-projeto\backend\app\api\tasks.py", line 29, in create_new_task
    task_created = await create_task(db, task)
                   ^^^^^^^^^^^^^^^^^^^^^^^^^^^
  File "C:\Users\V\Documents\DEV-VINI\github\m00-projeto\backend\app\services\task_service.py", line 23, in create_task
    await db.commit()
  File "C:\Users\V\Documents\DEV-VINI\github\m00-projeto\venv\Lib\site-packages\sqlalchemy\ext\asyncio\session.py", line 1014, in commit
    await greenlet_spawn(self.sync_session.commit)
  File "C:\Users\V\Documents\DEV-VINI\github\m00-projeto\venv\Lib\site-packages\sqlalchemy\util\_concurrency_py3k.py", line 203, in greenlet_spawn
    result = context.switch(value)
  File "C:\Users\V\Documents\DEV-VINI\github\m00-projeto\venv\Lib\site-packages\sqlalchemy\orm\session.py", line 2032, in commit
    trans.commit(_to_root=True)
    ~~~~~~~~~~~~^^^^^^^^^^^^^^^
  File "<string>", line 2, in commit
  File "C:\Users\V\Documents\DEV-VINI\github\m00-projeto\venv\Lib\site-packages\sqlalchemy\orm\state_changes.py", line 139, in _go
    ret_value = fn(self, *arg, **kw)
  File "C:\Users\V\Documents\DEV-VINI\github\m00-projeto\venv\Lib\site-packages\sqlalchemy\orm\session.py", line 1313, in commit
    self._prepare_impl()
    ~~~~~~~~~~~~~~~~~~^^
  File "<string>", line 2, in _prepare_impl
  File "C:\Users\V\Documents\DEV-VINI\github\m00-projeto\venv\Lib\site-packages\sqlalchemy\orm\state_changes.py", line 139, in _go
    ret_value = fn(self, *arg, **kw)
  File "C:\Users\V\Documents\DEV-VINI\github\m00-projeto\venv\Lib\site-packages\sqlalchemy\orm\session.py", line 1288, in _prepare_impl
    self.session.flush()
    ~~~~~~~~~~~~~~~~~~^^
  File "C:\Users\V\Documents\DEV-VINI\github\m00-projeto\venv\Lib\site-packages\sqlalchemy\orm\session.py", line 4345, in flush
    self._flush(objects)
    ~~~~~~~~~~~^^^^^^^^^
  File "C:\Users\V\Documents\DEV-VINI\github\m00-projeto\venv\Lib\site-packages\sqlalchemy\orm\session.py", line 4480, in _flush
    with util.safe_reraise():
         ~~~~~~~~~~~~~~~~~^^
  File "C:\Users\V\Documents\DEV-VINI\github\m00-projeto\venv\Lib\site-packages\sqlalchemy\util\langhelpers.py", line 224, in __exit__
    raise exc_value.with_traceback(exc_tb)
  File "C:\Users\V\Documents\DEV-VINI\github\m00-projeto\venv\Lib\site-packages\sqlalchemy\orm\session.py", line 4441, in _flush
    flush_context.execute()
    ~~~~~~~~~~~~~~~~~~~~~^^
  File "C:\Users\V\Documents\DEV-VINI\github\m00-projeto\venv\Lib\site-packages\sqlalchemy\orm\unitofwork.py", line 466, in execute
    rec.execute(self)
    ~~~~~~~~~~~^^^^^^
  File "C:\Users\V\Documents\DEV-VINI\github\m00-projeto\venv\Lib\site-packages\sqlalchemy\orm\unitofwork.py", line 642, in execute
    util.preloaded.orm_persistence.save_obj(
    ~~~~~~~~~~~~~~~~~~~~~~~~~~~~~~~~~~~~~~~^
        self.mapper,
        ^^^^^^^^^^^^
        uow.states_for_mapper_hierarchy(self.mapper, False, False),
        ^^^^^^^^^^^^^^^^^^^^^^^^^^^^^^^^^^^^^^^^^^^^^^^^^^^^^^^^^^^
        uow,
        ^^^^
    )
    ^
  File "C:\Users\V\Documents\DEV-VINI\github\m00-projeto\venv\Lib\site-packages\sqlalchemy\orm\persistence.py", line 93, in save_obj
    _emit_insert_statements(
    ~~~~~~~~~~~~~~~~~~~~~~~^
        base_mapper,
        ^^^^^^^^^^^^
    ...<3 lines>...
        insert,
        ^^^^^^^
    )
    ^
  File "C:\Users\V\Documents\DEV-VINI\github\m00-projeto\venv\Lib\site-packages\sqlalchemy\orm\persistence.py", line 1233, in _emit_insert_statements
    result = connection.execute(
        statement,
        params,
        execution_options=execution_options,
    )
  File "C:\Users\V\Documents\DEV-VINI\github\m00-projeto\venv\Lib\site-packages\sqlalchemy\engine\base.py", line 1415, in execute
    return meth(
        self,
        distilled_parameters,
        execution_options or NO_OPTIONS,
    )
  File "C:\Users\V\Documents\DEV-VINI\github\m00-projeto\venv\Lib\site-packages\sqlalchemy\sql\elements.py", line 523, in _execute_on_connection
    return connection._execute_clauseelement(
           ~~~~~~~~~~~~~~~~~~~~~~~~~~~~~~~~~^
        self, distilled_params, execution_options
        ^^^^^^^^^^^^^^^^^^^^^^^^^^^^^^^^^^^^^^^^^
    )
    ^
  File "C:\Users\V\Documents\DEV-VINI\github\m00-projeto\venv\Lib\site-packages\sqlalchemy\engine\base.py", line 1637, in _execute_clauseelement
    ret = self._execute_context(
        dialect,
    ...<8 lines>...
        cache_hit=cache_hit,
    )
  File "C:\Users\V\Documents\DEV-VINI\github\m00-projeto\venv\Lib\site-packages\sqlalchemy\engine\base.py", line 1842, in _execute_context
    return self._exec_single_context(
           ~~~~~~~~~~~~~~~~~~~~~~~~~^
        dialect, context, statement, parameters
        ^^^^^^^^^^^^^^^^^^^^^^^^^^^^^^^^^^^^^^^
    )
    ^
  File "C:\Users\V\Documents\DEV-VINI\github\m00-projeto\venv\Lib\site-packages\sqlalchemy\engine\base.py", line 1982, in _exec_single_context
    self._handle_dbapi_exception(
    ~~~~~~~~~~~~~~~~~~~~~~~~~~~~^
        e, str_statement, effective_parameters, cursor, context
        ^^^^^^^^^^^^^^^^^^^^^^^^^^^^^^^^^^^^^^^^^^^^^^^^^^^^^^^
    )
    ^
  File "C:\Users\V\Documents\DEV-VINI\github\m00-projeto\venv\Lib\site-packages\sqlalchemy\engine\base.py", line 2351, in _handle_dbapi_exception
    raise sqlalchemy_exception.with_traceback(exc_info[2]) from e
  File "C:\Users\V\Documents\DEV-VINI\github\m00-projeto\venv\Lib\site-packages\sqlalchemy\engine\base.py", line 1963, in _exec_single_context
    self.dialect.do_execute(
    ~~~~~~~~~~~~~~~~~~~~~~~^
        cursor, str_statement, effective_parameters, context
        ^^^^^^^^^^^^^^^^^^^^^^^^^^^^^^^^^^^^^^^^^^^^^^^^^^^^
    )
    ^
  File "C:\Users\V\Documents\DEV-VINI\github\m00-projeto\venv\Lib\site-packages\sqlalchemy\engine\default.py", line 943, in do_execute
    cursor.execute(statement, parameters)
    ~~~~~~~~~~~~~~^^^^^^^^^^^^^^^^^^^^^^^
  File "C:\Users\V\Documents\DEV-VINI\github\m00-projeto\venv\Lib\site-packages\sqlalchemy\dialects\sqlite\aiosqlite.py", line 149, in execute
    self._adapt_connection._handle_exception(error)
    ~~~~~~~~~~~~~~~~~~~~~~~~~~~~~~~~~~~~~~~~^^^^^^^
  File "C:\Users\V\Documents\DEV-VINI\github\m00-projeto\venv\Lib\site-packages\sqlalchemy\dialects\sqlite\aiosqlite.py", line 300, in _handle_exception
    raise error
  File "C:\Users\V\Documents\DEV-VINI\github\m00-projeto\venv\Lib\site-packages\sqlalchemy\dialects\sqlite\aiosqlite.py", line 131, in execute
    self.await_(_cursor.execute(operation, parameters))
    ~~~~~~~~~~~^^^^^^^^^^^^^^^^^^^^^^^^^^^^^^^^^^^^^^^^
  File "C:\Users\V\Documents\DEV-VINI\github\m00-projeto\venv\Lib\site-packages\sqlalchemy\util\_concurrency_py3k.py", line 132, in await_only
    return current.parent.switch(awaitable)  # type: ignore[no-any-return,attr-defined] # noqa: E501
           ~~~~~~~~~~~~~~~~~~~~~^^^^^^^^^^^
  File "C:\Users\V\Documents\DEV-VINI\github\m00-projeto\venv\Lib\site-packages\sqlalchemy\util\_concurrency_py3k.py", line 196, in greenlet_spawn
    value = await result
            ^^^^^^^^^^^^
  File "C:\Users\V\Documents\DEV-VINI\github\m00-projeto\venv\Lib\site-packages\aiosqlite\cursor.py", line 40, in execute
    await self._execute(self._cursor.execute, sql, parameters)
  File "C:\Users\V\Documents\DEV-VINI\github\m00-projeto\venv\Lib\site-packages\aiosqlite\cursor.py", line 32, in _execute
    return await self._conn._execute(fn, *args, **kwargs)
           ^^^^^^^^^^^^^^^^^^^^^^^^^^^^^^^^^^^^^^^^^^^^^^
  File "C:\Users\V\Documents\DEV-VINI\github\m00-projeto\venv\Lib\site-packages\aiosqlite\core.py", line 122, in _execute
    return await future
           ^^^^^^^^^^^^
  File "C:\Users\V\Documents\DEV-VINI\github\m00-projeto\venv\Lib\site-packages\aiosqlite\core.py", line 105, in run
    result = function()
sqlalchemy.exc.OperationalError: (sqlite3.OperationalError) no such table: tasks
[SQL: INSERT INTO tasks (title, description, completed) VALUES (?, ?, ?)]
[parameters: ('Tarefa PUT', 'Desc PUT', 0)]
(Background on this error at: https://sqlalche.me/e/20/e3q8)
2025-06-01 16:31:43,874 | ERROR | m00-backend | Erro inesperado em http://testserver/tasks/: (sqlite3.OperationalError) no such table: tasks
[SQL: INSERT INTO tasks (title, description, completed) VALUES (?, ?, ?)]
[parameters: ('Tarefa DELETE', 'Desc DELETE', 0)]
(Background on this error at: https://sqlalche.me/e/20/e3q8)
Traceback (most recent call last):
  File "C:\Users\V\Documents\DEV-VINI\github\m00-projeto\venv\Lib\site-packages\sqlalchemy\engine\base.py", line 1963, in _exec_single_context
    self.dialect.do_execute(
    ~~~~~~~~~~~~~~~~~~~~~~~^
        cursor, str_statement, effective_parameters, context
        ^^^^^^^^^^^^^^^^^^^^^^^^^^^^^^^^^^^^^^^^^^^^^^^^^^^^
    )
    ^
  File "C:\Users\V\Documents\DEV-VINI\github\m00-projeto\venv\Lib\site-packages\sqlalchemy\engine\default.py", line 943, in do_execute
    cursor.execute(statement, parameters)
    ~~~~~~~~~~~~~~^^^^^^^^^^^^^^^^^^^^^^^
  File "C:\Users\V\Documents\DEV-VINI\github\m00-projeto\venv\Lib\site-packages\sqlalchemy\dialects\sqlite\aiosqlite.py", line 149, in execute
    self._adapt_connection._handle_exception(error)
    ~~~~~~~~~~~~~~~~~~~~~~~~~~~~~~~~~~~~~~~~^^^^^^^
  File "C:\Users\V\Documents\DEV-VINI\github\m00-projeto\venv\Lib\site-packages\sqlalchemy\dialects\sqlite\aiosqlite.py", line 300, in _handle_exception
    raise error
  File "C:\Users\V\Documents\DEV-VINI\github\m00-projeto\venv\Lib\site-packages\sqlalchemy\dialects\sqlite\aiosqlite.py", line 131, in execute
    self.await_(_cursor.execute(operation, parameters))
    ~~~~~~~~~~~^^^^^^^^^^^^^^^^^^^^^^^^^^^^^^^^^^^^^^^^
  File "C:\Users\V\Documents\DEV-VINI\github\m00-projeto\venv\Lib\site-packages\sqlalchemy\util\_concurrency_py3k.py", line 132, in await_only
    return current.parent.switch(awaitable)  # type: ignore[no-any-return,attr-defined] # noqa: E501
           ~~~~~~~~~~~~~~~~~~~~~^^^^^^^^^^^
  File "C:\Users\V\Documents\DEV-VINI\github\m00-projeto\venv\Lib\site-packages\sqlalchemy\util\_concurrency_py3k.py", line 196, in greenlet_spawn
    value = await result
            ^^^^^^^^^^^^
  File "C:\Users\V\Documents\DEV-VINI\github\m00-projeto\venv\Lib\site-packages\aiosqlite\cursor.py", line 40, in execute
    await self._execute(self._cursor.execute, sql, parameters)
  File "C:\Users\V\Documents\DEV-VINI\github\m00-projeto\venv\Lib\site-packages\aiosqlite\cursor.py", line 32, in _execute
    return await self._conn._execute(fn, *args, **kwargs)
           ^^^^^^^^^^^^^^^^^^^^^^^^^^^^^^^^^^^^^^^^^^^^^^
  File "C:\Users\V\Documents\DEV-VINI\github\m00-projeto\venv\Lib\site-packages\aiosqlite\core.py", line 122, in _execute
    return await future
           ^^^^^^^^^^^^
  File "C:\Users\V\Documents\DEV-VINI\github\m00-projeto\venv\Lib\site-packages\aiosqlite\core.py", line 105, in run
    result = function()
sqlite3.OperationalError: no such table: tasks

The above exception was the direct cause of the following exception:

Traceback (most recent call last):
  File "C:\Users\V\Documents\DEV-VINI\github\m00-projeto\venv\Lib\site-packages\starlette\middleware\errors.py", line 165, in __call__
    await self.app(scope, receive, _send)
  File "C:\Users\V\Documents\DEV-VINI\github\m00-projeto\venv\Lib\site-packages\starlette\middleware\exceptions.py", line 62, in __call__
    await wrap_app_handling_exceptions(self.app, conn)(scope, receive, send)
  File "C:\Users\V\Documents\DEV-VINI\github\m00-projeto\venv\Lib\site-packages\starlette\_exception_handler.py", line 53, in wrapped_app
    raise exc
  File "C:\Users\V\Documents\DEV-VINI\github\m00-projeto\venv\Lib\site-packages\starlette\_exception_handler.py", line 42, in wrapped_app
    await app(scope, receive, sender)
  File "C:\Users\V\Documents\DEV-VINI\github\m00-projeto\venv\Lib\site-packages\starlette\routing.py", line 714, in __call__
    await self.middleware_stack(scope, receive, send)
  File "C:\Users\V\Documents\DEV-VINI\github\m00-projeto\venv\Lib\site-packages\starlette\routing.py", line 734, in app
    await route.handle(scope, receive, send)
  File "C:\Users\V\Documents\DEV-VINI\github\m00-projeto\venv\Lib\site-packages\starlette\routing.py", line 288, in handle
    await self.app(scope, receive, send)
  File "C:\Users\V\Documents\DEV-VINI\github\m00-projeto\venv\Lib\site-packages\starlette\routing.py", line 76, in app
    await wrap_app_handling_exceptions(app, request)(scope, receive, send)
  File "C:\Users\V\Documents\DEV-VINI\github\m00-projeto\venv\Lib\site-packages\starlette\_exception_handler.py", line 53, in wrapped_app
    raise exc
  File "C:\Users\V\Documents\DEV-VINI\github\m00-projeto\venv\Lib\site-packages\starlette\_exception_handler.py", line 42, in wrapped_app
    await app(scope, receive, sender)
  File "C:\Users\V\Documents\DEV-VINI\github\m00-projeto\venv\Lib\site-packages\starlette\routing.py", line 73, in app
    response = await f(request)
               ^^^^^^^^^^^^^^^^
  File "C:\Users\V\Documents\DEV-VINI\github\m00-projeto\venv\Lib\site-packages\fastapi\routing.py", line 301, in app
    raw_response = await run_endpoint_function(
                   ^^^^^^^^^^^^^^^^^^^^^^^^^^^^
    ...<3 lines>...
    )
    ^
  File "C:\Users\V\Documents\DEV-VINI\github\m00-projeto\venv\Lib\site-packages\fastapi\routing.py", line 212, in run_endpoint_function
    return await dependant.call(**values)
           ^^^^^^^^^^^^^^^^^^^^^^^^^^^^^^
  File "C:\Users\V\Documents\DEV-VINI\github\m00-projeto\backend\app\api\tasks.py", line 29, in create_new_task
    task_created = await create_task(db, task)
                   ^^^^^^^^^^^^^^^^^^^^^^^^^^^
  File "C:\Users\V\Documents\DEV-VINI\github\m00-projeto\backend\app\services\task_service.py", line 23, in create_task
    await db.commit()
  File "C:\Users\V\Documents\DEV-VINI\github\m00-projeto\venv\Lib\site-packages\sqlalchemy\ext\asyncio\session.py", line 1014, in commit
    await greenlet_spawn(self.sync_session.commit)
  File "C:\Users\V\Documents\DEV-VINI\github\m00-projeto\venv\Lib\site-packages\sqlalchemy\util\_concurrency_py3k.py", line 203, in greenlet_spawn
    result = context.switch(value)
  File "C:\Users\V\Documents\DEV-VINI\github\m00-projeto\venv\Lib\site-packages\sqlalchemy\orm\session.py", line 2032, in commit
    trans.commit(_to_root=True)
    ~~~~~~~~~~~~^^^^^^^^^^^^^^^
  File "<string>", line 2, in commit
  File "C:\Users\V\Documents\DEV-VINI\github\m00-projeto\venv\Lib\site-packages\sqlalchemy\orm\state_changes.py", line 139, in _go
    ret_value = fn(self, *arg, **kw)
  File "C:\Users\V\Documents\DEV-VINI\github\m00-projeto\venv\Lib\site-packages\sqlalchemy\orm\session.py", line 1313, in commit
    self._prepare_impl()
    ~~~~~~~~~~~~~~~~~~^^
  File "<string>", line 2, in _prepare_impl
  File "C:\Users\V\Documents\DEV-VINI\github\m00-projeto\venv\Lib\site-packages\sqlalchemy\orm\state_changes.py", line 139, in _go
    ret_value = fn(self, *arg, **kw)
  File "C:\Users\V\Documents\DEV-VINI\github\m00-projeto\venv\Lib\site-packages\sqlalchemy\orm\session.py", line 1288, in _prepare_impl
    self.session.flush()
    ~~~~~~~~~~~~~~~~~~^^
  File "C:\Users\V\Documents\DEV-VINI\github\m00-projeto\venv\Lib\site-packages\sqlalchemy\orm\session.py", line 4345, in flush
    self._flush(objects)
    ~~~~~~~~~~~^^^^^^^^^
  File "C:\Users\V\Documents\DEV-VINI\github\m00-projeto\venv\Lib\site-packages\sqlalchemy\orm\session.py", line 4480, in _flush
    with util.safe_reraise():
         ~~~~~~~~~~~~~~~~~^^
  File "C:\Users\V\Documents\DEV-VINI\github\m00-projeto\venv\Lib\site-packages\sqlalchemy\util\langhelpers.py", line 224, in __exit__
    raise exc_value.with_traceback(exc_tb)
  File "C:\Users\V\Documents\DEV-VINI\github\m00-projeto\venv\Lib\site-packages\sqlalchemy\orm\session.py", line 4441, in _flush
    flush_context.execute()
    ~~~~~~~~~~~~~~~~~~~~~^^
  File "C:\Users\V\Documents\DEV-VINI\github\m00-projeto\venv\Lib\site-packages\sqlalchemy\orm\unitofwork.py", line 466, in execute
    rec.execute(self)
    ~~~~~~~~~~~^^^^^^
  File "C:\Users\V\Documents\DEV-VINI\github\m00-projeto\venv\Lib\site-packages\sqlalchemy\orm\unitofwork.py", line 642, in execute
    util.preloaded.orm_persistence.save_obj(
    ~~~~~~~~~~~~~~~~~~~~~~~~~~~~~~~~~~~~~~~^
        self.mapper,
        ^^^^^^^^^^^^
        uow.states_for_mapper_hierarchy(self.mapper, False, False),
        ^^^^^^^^^^^^^^^^^^^^^^^^^^^^^^^^^^^^^^^^^^^^^^^^^^^^^^^^^^^
        uow,
        ^^^^
    )
    ^
  File "C:\Users\V\Documents\DEV-VINI\github\m00-projeto\venv\Lib\site-packages\sqlalchemy\orm\persistence.py", line 93, in save_obj
    _emit_insert_statements(
    ~~~~~~~~~~~~~~~~~~~~~~~^
        base_mapper,
        ^^^^^^^^^^^^
    ...<3 lines>...
        insert,
        ^^^^^^^
    )
    ^
  File "C:\Users\V\Documents\DEV-VINI\github\m00-projeto\venv\Lib\site-packages\sqlalchemy\orm\persistence.py", line 1233, in _emit_insert_statements
    result = connection.execute(
        statement,
        params,
        execution_options=execution_options,
    )
  File "C:\Users\V\Documents\DEV-VINI\github\m00-projeto\venv\Lib\site-packages\sqlalchemy\engine\base.py", line 1415, in execute
    return meth(
        self,
        distilled_parameters,
        execution_options or NO_OPTIONS,
    )
  File "C:\Users\V\Documents\DEV-VINI\github\m00-projeto\venv\Lib\site-packages\sqlalchemy\sql\elements.py", line 523, in _execute_on_connection
    return connection._execute_clauseelement(
           ~~~~~~~~~~~~~~~~~~~~~~~~~~~~~~~~~^
        self, distilled_params, execution_options
        ^^^^^^^^^^^^^^^^^^^^^^^^^^^^^^^^^^^^^^^^^
    )
    ^
  File "C:\Users\V\Documents\DEV-VINI\github\m00-projeto\venv\Lib\site-packages\sqlalchemy\engine\base.py", line 1637, in _execute_clauseelement
    ret = self._execute_context(
        dialect,
    ...<8 lines>...
        cache_hit=cache_hit,
    )
  File "C:\Users\V\Documents\DEV-VINI\github\m00-projeto\venv\Lib\site-packages\sqlalchemy\engine\base.py", line 1842, in _execute_context
    return self._exec_single_context(
           ~~~~~~~~~~~~~~~~~~~~~~~~~^
        dialect, context, statement, parameters
        ^^^^^^^^^^^^^^^^^^^^^^^^^^^^^^^^^^^^^^^
    )
    ^
  File "C:\Users\V\Documents\DEV-VINI\github\m00-projeto\venv\Lib\site-packages\sqlalchemy\engine\base.py", line 1982, in _exec_single_context
    self._handle_dbapi_exception(
    ~~~~~~~~~~~~~~~~~~~~~~~~~~~~^
        e, str_statement, effective_parameters, cursor, context
        ^^^^^^^^^^^^^^^^^^^^^^^^^^^^^^^^^^^^^^^^^^^^^^^^^^^^^^^
    )
    ^
  File "C:\Users\V\Documents\DEV-VINI\github\m00-projeto\venv\Lib\site-packages\sqlalchemy\engine\base.py", line 2351, in _handle_dbapi_exception
    raise sqlalchemy_exception.with_traceback(exc_info[2]) from e
  File "C:\Users\V\Documents\DEV-VINI\github\m00-projeto\venv\Lib\site-packages\sqlalchemy\engine\base.py", line 1963, in _exec_single_context
    self.dialect.do_execute(
    ~~~~~~~~~~~~~~~~~~~~~~~^
        cursor, str_statement, effective_parameters, context
        ^^^^^^^^^^^^^^^^^^^^^^^^^^^^^^^^^^^^^^^^^^^^^^^^^^^^
    )
    ^
  File "C:\Users\V\Documents\DEV-VINI\github\m00-projeto\venv\Lib\site-packages\sqlalchemy\engine\default.py", line 943, in do_execute
    cursor.execute(statement, parameters)
    ~~~~~~~~~~~~~~^^^^^^^^^^^^^^^^^^^^^^^
  File "C:\Users\V\Documents\DEV-VINI\github\m00-projeto\venv\Lib\site-packages\sqlalchemy\dialects\sqlite\aiosqlite.py", line 149, in execute
    self._adapt_connection._handle_exception(error)
    ~~~~~~~~~~~~~~~~~~~~~~~~~~~~~~~~~~~~~~~~^^^^^^^
  File "C:\Users\V\Documents\DEV-VINI\github\m00-projeto\venv\Lib\site-packages\sqlalchemy\dialects\sqlite\aiosqlite.py", line 300, in _handle_exception
    raise error
  File "C:\Users\V\Documents\DEV-VINI\github\m00-projeto\venv\Lib\site-packages\sqlalchemy\dialects\sqlite\aiosqlite.py", line 131, in execute
    self.await_(_cursor.execute(operation, parameters))
    ~~~~~~~~~~~^^^^^^^^^^^^^^^^^^^^^^^^^^^^^^^^^^^^^^^^
  File "C:\Users\V\Documents\DEV-VINI\github\m00-projeto\venv\Lib\site-packages\sqlalchemy\util\_concurrency_py3k.py", line 132, in await_only
    return current.parent.switch(awaitable)  # type: ignore[no-any-return,attr-defined] # noqa: E501
           ~~~~~~~~~~~~~~~~~~~~~^^^^^^^^^^^
  File "C:\Users\V\Documents\DEV-VINI\github\m00-projeto\venv\Lib\site-packages\sqlalchemy\util\_concurrency_py3k.py", line 196, in greenlet_spawn
    value = await result
            ^^^^^^^^^^^^
  File "C:\Users\V\Documents\DEV-VINI\github\m00-projeto\venv\Lib\site-packages\aiosqlite\cursor.py", line 40, in execute
    await self._execute(self._cursor.execute, sql, parameters)
  File "C:\Users\V\Documents\DEV-VINI\github\m00-projeto\venv\Lib\site-packages\aiosqlite\cursor.py", line 32, in _execute
    return await self._conn._execute(fn, *args, **kwargs)
           ^^^^^^^^^^^^^^^^^^^^^^^^^^^^^^^^^^^^^^^^^^^^^^
  File "C:\Users\V\Documents\DEV-VINI\github\m00-projeto\venv\Lib\site-packages\aiosqlite\core.py", line 122, in _execute
    return await future
           ^^^^^^^^^^^^
  File "C:\Users\V\Documents\DEV-VINI\github\m00-projeto\venv\Lib\site-packages\aiosqlite\core.py", line 105, in run
    result = function()
sqlalchemy.exc.OperationalError: (sqlite3.OperationalError) no such table: tasks
[SQL: INSERT INTO tasks (title, description, completed) VALUES (?, ?, ?)]
[parameters: ('Tarefa DELETE', 'Desc DELETE', 0)]
(Background on this error at: https://sqlalche.me/e/20/e3q8)
2025-06-01 16:35:53,762 | INFO | m00-backend | Iniciando m00-backend
2025-06-01 16:35:53,762 | INFO | m00-backend | === Teste de gravação em arquivo de log ===
2025-06-01 16:35:54,204 | INFO | m00-backend | Rota raiz acessada
2025-06-01 16:35:54,946 | ERROR | m00-backend | HTTP error 404 em http://testserver/tasks/1: Task não encontrada
2025-06-01 16:36:12,104 | INFO | m00-backend | Iniciando m00-backend
2025-06-01 16:36:12,104 | INFO | m00-backend | === Teste de gravação em arquivo de log ===
2025-06-01 16:36:12,546 | INFO | m00-backend | Rota raiz acessada
2025-06-01 16:36:13,283 | ERROR | m00-backend | HTTP error 404 em http://testserver/tasks/1: Task não encontrada
2025-06-01 16:38:07,372 | INFO | m00-backend | Iniciando m00-backend
2025-06-01 16:38:07,373 | INFO | m00-backend | === Teste de gravação em arquivo de log ===
2025-06-01 16:38:07,622 | INFO | m00-backend | Rota raiz acessada
2025-06-01 16:38:07,771 | ERROR | m00-backend | HTTP error 404 em http://testserver/tasks/4: Task não encontrada
2025-06-01 16:42:24,230 | INFO | m00-backend | Iniciando m00-backend
2025-06-01 16:42:24,230 | INFO | m00-backend | === Teste de gravação em arquivo de log ===
2025-06-01 16:43:52,612 | INFO | m00-backend | Iniciando m00-backend
2025-06-01 16:43:52,612 | INFO | m00-backend | === Teste de gravação em arquivo de log ===
2025-06-01 16:43:52,936 | ERROR | m00-backend | HTTP error 401 em http://testserver/auth/token: Usuário ou senha incorretos
2025-06-01 16:43:53,945 | INFO | m00-backend | Rota raiz acessada
2025-06-01 16:43:54,261 | ERROR | m00-backend | HTTP error 404 em http://testserver/tasks/1: Task não encontrada
2025-06-01 16:46:38,245 | INFO | m00-backend | Iniciando m00-backend
2025-06-01 16:46:38,245 | INFO | m00-backend | === Teste de gravação em arquivo de log ===
2025-06-01 16:46:38,574 | ERROR | m00-backend | HTTP error 401 em http://testserver/auth/token: Usuário ou senha incorretos
2025-06-01 16:46:39,557 | INFO | m00-backend | Rota raiz acessada
2025-06-01 16:46:39,713 | ERROR | m00-backend | HTTP error 404 em http://testserver/tasks/1: Task não encontrada
